{
 "cells": [
  {
   "cell_type": "markdown",
   "metadata": {},
   "source": [
    "# Exploratory Analysis"
   ]
  },
  {
   "cell_type": "code",
   "execution_count": 1,
   "metadata": {},
   "outputs": [],
   "source": [
    "%load_ext autoreload\n",
    "%autoreload 2"
   ]
  },
  {
   "cell_type": "code",
   "execution_count": 2,
   "metadata": {},
   "outputs": [],
   "source": [
    "from olist.data import Olist\n",
    "data = Olist().get_data()"
   ]
  },
  {
   "cell_type": "markdown",
   "metadata": {},
   "source": [
    "### 1 - Run an exploratory analysis with [pandas profiling](https://github.com/pandas-profiling/pandas-profiling)"
   ]
  },
  {
   "cell_type": "code",
   "execution_count": 3,
   "metadata": {},
   "outputs": [
    {
     "name": "stdout",
     "output_type": "stream",
     "text": [
      "Collecting pandas-profiling\n",
      "  Downloading pandas_profiling-2.10.0-py2.py3-none-any.whl (239 kB)\n",
      "Requirement already satisfied: jinja2>=2.11.1 in c:\\users\\juangabriel\\.venvs\\lewagon\\lib\\site-packages (from pandas-profiling) (2.11.2)\n",
      "Collecting confuse>=1.0.0\n",
      "  Downloading confuse-1.4.0-py2.py3-none-any.whl (21 kB)\n",
      "Requirement already satisfied: tqdm>=4.48.2 in c:\\users\\juangabriel\\.venvs\\lewagon\\lib\\site-packages (from pandas-profiling) (4.51.0)\n",
      "Collecting scipy>=1.4.1\n",
      "  Downloading scipy-1.6.0-cp37-cp37m-win_amd64.whl (32.5 MB)\n",
      "Collecting phik>=0.10.0\n",
      "  Downloading phik-0.11.0.tar.gz (594 kB)\n",
      "Requirement already satisfied: numpy>=1.16.0 in c:\\users\\juangabriel\\.venvs\\lewagon\\lib\\site-packages (from pandas-profiling) (1.18.4)\n",
      "Collecting tangled-up-in-unicode>=0.0.6\n",
      "  Downloading tangled_up_in_unicode-0.0.6-py3-none-any.whl (3.1 MB)\n",
      "Requirement already satisfied: ipywidgets>=7.5.1 in c:\\users\\juangabriel\\.venvs\\lewagon\\lib\\site-packages (from pandas-profiling) (7.5.1)\n",
      "Requirement already satisfied: attrs>=19.3.0 in c:\\users\\juangabriel\\.venvs\\lewagon\\lib\\site-packages (from pandas-profiling) (20.2.0)\n",
      "Requirement already satisfied: requests>=2.24.0 in c:\\users\\juangabriel\\.venvs\\lewagon\\lib\\site-packages (from pandas-profiling) (2.24.0)\n",
      "Requirement already satisfied: seaborn>=0.10.1 in c:\\users\\juangabriel\\.venvs\\lewagon\\lib\\site-packages (from pandas-profiling) (0.11.0)\n",
      "Collecting visions[type_image_path]==0.6.0\n",
      "  Downloading visions-0.6.0-py3-none-any.whl (75 kB)\n",
      "Collecting htmlmin>=0.1.12\n",
      "  Downloading htmlmin-0.1.12.tar.gz (19 kB)\n",
      "Requirement already satisfied: joblib in c:\\users\\juangabriel\\.venvs\\lewagon\\lib\\site-packages (from pandas-profiling) (0.14.1)\n",
      "Collecting missingno>=0.4.2\n",
      "  Downloading missingno-0.4.2-py3-none-any.whl (9.7 kB)\n",
      "Collecting pandas!=1.0.0,!=1.0.1,!=1.0.2,!=1.1.0,>=0.25.3\n",
      "  Downloading pandas-1.2.0-cp37-cp37m-win_amd64.whl (9.1 MB)\n",
      "Requirement already satisfied: matplotlib>=3.2.0 in c:\\users\\juangabriel\\.venvs\\lewagon\\lib\\site-packages (from pandas-profiling) (3.3.2)\n",
      "Requirement already satisfied: MarkupSafe>=0.23 in c:\\users\\juangabriel\\.venvs\\lewagon\\lib\\site-packages (from jinja2>=2.11.1->pandas-profiling) (1.1.1)\n",
      "Requirement already satisfied: pyyaml in c:\\users\\juangabriel\\.venvs\\lewagon\\lib\\site-packages (from confuse>=1.0.0->pandas-profiling) (5.3.1)\n",
      "Collecting numba>=0.38.1\n",
      "  Downloading numba-0.52.0-cp37-cp37m-win_amd64.whl (2.3 MB)\n",
      "Requirement already satisfied: ipython>=4.0.0; python_version >= \"3.3\" in c:\\users\\juangabriel\\.venvs\\lewagon\\lib\\site-packages (from ipywidgets>=7.5.1->pandas-profiling) (7.18.1)\n",
      "Requirement already satisfied: widgetsnbextension~=3.5.0 in c:\\users\\juangabriel\\.venvs\\lewagon\\lib\\site-packages (from ipywidgets>=7.5.1->pandas-profiling) (3.5.1)\n",
      "Requirement already satisfied: ipykernel>=4.5.1 in c:\\users\\juangabriel\\.venvs\\lewagon\\lib\\site-packages (from ipywidgets>=7.5.1->pandas-profiling) (5.3.4)\n",
      "Requirement already satisfied: traitlets>=4.3.1 in c:\\users\\juangabriel\\.venvs\\lewagon\\lib\\site-packages (from ipywidgets>=7.5.1->pandas-profiling) (5.0.4)\n",
      "Requirement already satisfied: nbformat>=4.2.0 in c:\\users\\juangabriel\\.venvs\\lewagon\\lib\\site-packages (from ipywidgets>=7.5.1->pandas-profiling) (5.0.7)\n",
      "Requirement already satisfied: certifi>=2017.4.17 in c:\\users\\juangabriel\\.venvs\\lewagon\\lib\\site-packages (from requests>=2.24.0->pandas-profiling) (2020.6.20)\n",
      "Requirement already satisfied: urllib3!=1.25.0,!=1.25.1,<1.26,>=1.21.1 in c:\\users\\juangabriel\\.venvs\\lewagon\\lib\\site-packages (from requests>=2.24.0->pandas-profiling) (1.25.10)\n",
      "Requirement already satisfied: chardet<4,>=3.0.2 in c:\\users\\juangabriel\\.venvs\\lewagon\\lib\\site-packages (from requests>=2.24.0->pandas-profiling) (3.0.4)\n",
      "Requirement already satisfied: idna<3,>=2.5 in c:\\users\\juangabriel\\.venvs\\lewagon\\lib\\site-packages (from requests>=2.24.0->pandas-profiling) (2.10)\n",
      "Requirement already satisfied: networkx>=2.4 in c:\\users\\juangabriel\\.venvs\\lewagon\\lib\\site-packages (from visions[type_image_path]==0.6.0->pandas-profiling) (2.5)\n",
      "Collecting imagehash; extra == \"type_image_path\"\n",
      "  Downloading ImageHash-4.2.0-py2.py3-none-any.whl (295 kB)\n",
      "Requirement already satisfied: Pillow; extra == \"type_image_path\" in c:\\users\\juangabriel\\.venvs\\lewagon\\lib\\site-packages (from visions[type_image_path]==0.6.0->pandas-profiling) (7.2.0)\n",
      "Requirement already satisfied: python-dateutil>=2.7.3 in c:\\users\\juangabriel\\.venvs\\lewagon\\lib\\site-packages (from pandas!=1.0.0,!=1.0.1,!=1.0.2,!=1.1.0,>=0.25.3->pandas-profiling) (2.8.1)\n",
      "Requirement already satisfied: pytz>=2017.3 in c:\\users\\juangabriel\\.venvs\\lewagon\\lib\\site-packages (from pandas!=1.0.0,!=1.0.1,!=1.0.2,!=1.1.0,>=0.25.3->pandas-profiling) (2020.1)\n",
      "Requirement already satisfied: cycler>=0.10 in c:\\users\\juangabriel\\.venvs\\lewagon\\lib\\site-packages (from matplotlib>=3.2.0->pandas-profiling) (0.10.0)\n",
      "Requirement already satisfied: pyparsing!=2.0.4,!=2.1.2,!=2.1.6,>=2.0.3 in c:\\users\\juangabriel\\.venvs\\lewagon\\lib\\site-packages (from matplotlib>=3.2.0->pandas-profiling) (2.4.7)\n",
      "Requirement already satisfied: kiwisolver>=1.0.1 in c:\\users\\juangabriel\\.venvs\\lewagon\\lib\\site-packages (from matplotlib>=3.2.0->pandas-profiling) (1.2.0)\n",
      "Collecting llvmlite<0.36,>=0.35.0\n",
      "  Downloading llvmlite-0.35.0-cp37-cp37m-win_amd64.whl (16.0 MB)\n",
      "Requirement already satisfied: setuptools in c:\\users\\juangabriel\\.venvs\\lewagon\\lib\\site-packages (from numba>=0.38.1->phik>=0.10.0->pandas-profiling) (41.2.0)\n",
      "Requirement already satisfied: backcall in c:\\users\\juangabriel\\.venvs\\lewagon\\lib\\site-packages (from ipython>=4.0.0; python_version >= \"3.3\"->ipywidgets>=7.5.1->pandas-profiling) (0.2.0)\n",
      "Requirement already satisfied: colorama; sys_platform == \"win32\" in c:\\users\\juangabriel\\.venvs\\lewagon\\lib\\site-packages (from ipython>=4.0.0; python_version >= \"3.3\"->ipywidgets>=7.5.1->pandas-profiling) (0.4.3)\n",
      "Requirement already satisfied: pickleshare in c:\\users\\juangabriel\\.venvs\\lewagon\\lib\\site-packages (from ipython>=4.0.0; python_version >= \"3.3\"->ipywidgets>=7.5.1->pandas-profiling) (0.7.5)\n",
      "Requirement already satisfied: decorator in c:\\users\\juangabriel\\.venvs\\lewagon\\lib\\site-packages (from ipython>=4.0.0; python_version >= \"3.3\"->ipywidgets>=7.5.1->pandas-profiling) (4.4.2)\n",
      "Requirement already satisfied: jedi>=0.10 in c:\\users\\juangabriel\\.venvs\\lewagon\\lib\\site-packages (from ipython>=4.0.0; python_version >= \"3.3\"->ipywidgets>=7.5.1->pandas-profiling) (0.17.2)\n",
      "Requirement already satisfied: pygments in c:\\users\\juangabriel\\.venvs\\lewagon\\lib\\site-packages (from ipython>=4.0.0; python_version >= \"3.3\"->ipywidgets>=7.5.1->pandas-profiling) (2.7.1)\n",
      "Requirement already satisfied: prompt-toolkit!=3.0.0,!=3.0.1,<3.1.0,>=2.0.0 in c:\\users\\juangabriel\\.venvs\\lewagon\\lib\\site-packages (from ipython>=4.0.0; python_version >= \"3.3\"->ipywidgets>=7.5.1->pandas-profiling) (3.0.7)\n",
      "Requirement already satisfied: notebook>=4.4.1 in c:\\users\\juangabriel\\.venvs\\lewagon\\lib\\site-packages (from widgetsnbextension~=3.5.0->ipywidgets>=7.5.1->pandas-profiling) (6.1.4)\n",
      "Requirement already satisfied: tornado>=4.2 in c:\\users\\juangabriel\\.venvs\\lewagon\\lib\\site-packages (from ipykernel>=4.5.1->ipywidgets>=7.5.1->pandas-profiling) (6.0.4)\n",
      "Requirement already satisfied: jupyter-client in c:\\users\\juangabriel\\.venvs\\lewagon\\lib\\site-packages (from ipykernel>=4.5.1->ipywidgets>=7.5.1->pandas-profiling) (6.1.7)\n",
      "Requirement already satisfied: ipython-genutils in c:\\users\\juangabriel\\.venvs\\lewagon\\lib\\site-packages (from traitlets>=4.3.1->ipywidgets>=7.5.1->pandas-profiling) (0.2.0)\n",
      "Requirement already satisfied: jupyter-core in c:\\users\\juangabriel\\.venvs\\lewagon\\lib\\site-packages (from nbformat>=4.2.0->ipywidgets>=7.5.1->pandas-profiling) (4.6.3)\n",
      "Requirement already satisfied: jsonschema!=2.5.0,>=2.4 in c:\\users\\juangabriel\\.venvs\\lewagon\\lib\\site-packages (from nbformat>=4.2.0->ipywidgets>=7.5.1->pandas-profiling) (3.2.0)\n",
      "Requirement already satisfied: six in c:\\users\\juangabriel\\.venvs\\lewagon\\lib\\site-packages (from imagehash; extra == \"type_image_path\"->visions[type_image_path]==0.6.0->pandas-profiling) (1.15.0)\n",
      "Requirement already satisfied: PyWavelets in c:\\users\\juangabriel\\.venvs\\lewagon\\lib\\site-packages (from imagehash; extra == \"type_image_path\"->visions[type_image_path]==0.6.0->pandas-profiling) (1.1.1)\n",
      "Requirement already satisfied: parso<0.8.0,>=0.7.0 in c:\\users\\juangabriel\\.venvs\\lewagon\\lib\\site-packages (from jedi>=0.10->ipython>=4.0.0; python_version >= \"3.3\"->ipywidgets>=7.5.1->pandas-profiling) (0.7.1)\n",
      "Requirement already satisfied: wcwidth in c:\\users\\juangabriel\\.venvs\\lewagon\\lib\\site-packages (from prompt-toolkit!=3.0.0,!=3.0.1,<3.1.0,>=2.0.0->ipython>=4.0.0; python_version >= \"3.3\"->ipywidgets>=7.5.1->pandas-profiling) (0.2.5)\n",
      "Requirement already satisfied: pyzmq>=17 in c:\\users\\juangabriel\\.venvs\\lewagon\\lib\\site-packages (from notebook>=4.4.1->widgetsnbextension~=3.5.0->ipywidgets>=7.5.1->pandas-profiling) (19.0.2)\n",
      "Requirement already satisfied: prometheus-client in c:\\users\\juangabriel\\.venvs\\lewagon\\lib\\site-packages (from notebook>=4.4.1->widgetsnbextension~=3.5.0->ipywidgets>=7.5.1->pandas-profiling) (0.8.0)\n",
      "Requirement already satisfied: Send2Trash in c:\\users\\juangabriel\\.venvs\\lewagon\\lib\\site-packages (from notebook>=4.4.1->widgetsnbextension~=3.5.0->ipywidgets>=7.5.1->pandas-profiling) (1.5.0)\n",
      "Requirement already satisfied: argon2-cffi in c:\\users\\juangabriel\\.venvs\\lewagon\\lib\\site-packages (from notebook>=4.4.1->widgetsnbextension~=3.5.0->ipywidgets>=7.5.1->pandas-profiling) (20.1.0)\n",
      "Requirement already satisfied: nbconvert in c:\\users\\juangabriel\\.venvs\\lewagon\\lib\\site-packages (from notebook>=4.4.1->widgetsnbextension~=3.5.0->ipywidgets>=7.5.1->pandas-profiling) (6.0.7)\n",
      "Requirement already satisfied: terminado>=0.8.3 in c:\\users\\juangabriel\\.venvs\\lewagon\\lib\\site-packages (from notebook>=4.4.1->widgetsnbextension~=3.5.0->ipywidgets>=7.5.1->pandas-profiling) (0.9.1)\n",
      "Requirement already satisfied: pywin32>=1.0; sys_platform == \"win32\" in c:\\users\\juangabriel\\.venvs\\lewagon\\lib\\site-packages (from jupyter-core->nbformat>=4.2.0->ipywidgets>=7.5.1->pandas-profiling) (227)\n",
      "Requirement already satisfied: pyrsistent>=0.14.0 in c:\\users\\juangabriel\\.venvs\\lewagon\\lib\\site-packages (from jsonschema!=2.5.0,>=2.4->nbformat>=4.2.0->ipywidgets>=7.5.1->pandas-profiling) (0.17.3)\n",
      "Requirement already satisfied: importlib-metadata; python_version < \"3.8\" in c:\\users\\juangabriel\\.venvs\\lewagon\\lib\\site-packages (from jsonschema!=2.5.0,>=2.4->nbformat>=4.2.0->ipywidgets>=7.5.1->pandas-profiling) (2.0.0)\n",
      "Requirement already satisfied: cffi>=1.0.0 in c:\\users\\juangabriel\\.venvs\\lewagon\\lib\\site-packages (from argon2-cffi->notebook>=4.4.1->widgetsnbextension~=3.5.0->ipywidgets>=7.5.1->pandas-profiling) (1.14.3)\n",
      "Requirement already satisfied: bleach in c:\\users\\juangabriel\\.venvs\\lewagon\\lib\\site-packages (from nbconvert->notebook>=4.4.1->widgetsnbextension~=3.5.0->ipywidgets>=7.5.1->pandas-profiling) (3.2.1)\n",
      "Requirement already satisfied: testpath in c:\\users\\juangabriel\\.venvs\\lewagon\\lib\\site-packages (from nbconvert->notebook>=4.4.1->widgetsnbextension~=3.5.0->ipywidgets>=7.5.1->pandas-profiling) (0.4.4)\n",
      "Requirement already satisfied: pandocfilters>=1.4.1 in c:\\users\\juangabriel\\.venvs\\lewagon\\lib\\site-packages (from nbconvert->notebook>=4.4.1->widgetsnbextension~=3.5.0->ipywidgets>=7.5.1->pandas-profiling) (1.4.2)\n",
      "Requirement already satisfied: nbclient<0.6.0,>=0.5.0 in c:\\users\\juangabriel\\.venvs\\lewagon\\lib\\site-packages (from nbconvert->notebook>=4.4.1->widgetsnbextension~=3.5.0->ipywidgets>=7.5.1->pandas-profiling) (0.5.0)\n",
      "Requirement already satisfied: jupyterlab-pygments in c:\\users\\juangabriel\\.venvs\\lewagon\\lib\\site-packages (from nbconvert->notebook>=4.4.1->widgetsnbextension~=3.5.0->ipywidgets>=7.5.1->pandas-profiling) (0.1.2)\n",
      "Requirement already satisfied: entrypoints>=0.2.2 in c:\\users\\juangabriel\\.venvs\\lewagon\\lib\\site-packages (from nbconvert->notebook>=4.4.1->widgetsnbextension~=3.5.0->ipywidgets>=7.5.1->pandas-profiling) (0.3)\n",
      "Requirement already satisfied: mistune<2,>=0.8.1 in c:\\users\\juangabriel\\.venvs\\lewagon\\lib\\site-packages (from nbconvert->notebook>=4.4.1->widgetsnbextension~=3.5.0->ipywidgets>=7.5.1->pandas-profiling) (0.8.4)\n",
      "Requirement already satisfied: defusedxml in c:\\users\\juangabriel\\.venvs\\lewagon\\lib\\site-packages (from nbconvert->notebook>=4.4.1->widgetsnbextension~=3.5.0->ipywidgets>=7.5.1->pandas-profiling) (0.6.0)\n",
      "Requirement already satisfied: pywinpty>=0.5; os_name == \"nt\" in c:\\users\\juangabriel\\.venvs\\lewagon\\lib\\site-packages (from terminado>=0.8.3->notebook>=4.4.1->widgetsnbextension~=3.5.0->ipywidgets>=7.5.1->pandas-profiling) (0.5.7)\n",
      "Requirement already satisfied: zipp>=0.5 in c:\\users\\juangabriel\\.venvs\\lewagon\\lib\\site-packages (from importlib-metadata; python_version < \"3.8\"->jsonschema!=2.5.0,>=2.4->nbformat>=4.2.0->ipywidgets>=7.5.1->pandas-profiling) (3.3.0)\n",
      "Requirement already satisfied: pycparser in c:\\users\\juangabriel\\.venvs\\lewagon\\lib\\site-packages (from cffi>=1.0.0->argon2-cffi->notebook>=4.4.1->widgetsnbextension~=3.5.0->ipywidgets>=7.5.1->pandas-profiling) (2.20)\n",
      "Requirement already satisfied: packaging in c:\\users\\juangabriel\\.venvs\\lewagon\\lib\\site-packages (from bleach->nbconvert->notebook>=4.4.1->widgetsnbextension~=3.5.0->ipywidgets>=7.5.1->pandas-profiling) (20.4)\n",
      "Requirement already satisfied: webencodings in c:\\users\\juangabriel\\.venvs\\lewagon\\lib\\site-packages (from bleach->nbconvert->notebook>=4.4.1->widgetsnbextension~=3.5.0->ipywidgets>=7.5.1->pandas-profiling) (0.5.1)\n",
      "Requirement already satisfied: nest-asyncio in c:\\users\\juangabriel\\.venvs\\lewagon\\lib\\site-packages (from nbclient<0.6.0,>=0.5.0->nbconvert->notebook>=4.4.1->widgetsnbextension~=3.5.0->ipywidgets>=7.5.1->pandas-profiling) (1.4.1)\n",
      "Requirement already satisfied: async-generator in c:\\users\\juangabriel\\.venvs\\lewagon\\lib\\site-packages (from nbclient<0.6.0,>=0.5.0->nbconvert->notebook>=4.4.1->widgetsnbextension~=3.5.0->ipywidgets>=7.5.1->pandas-profiling) (1.10)\n",
      "Building wheels for collected packages: phik, htmlmin\n",
      "  Building wheel for phik (setup.py): started\n",
      "  Building wheel for phik (setup.py): finished with status 'done'\n",
      "  Created wheel for phik: filename=phik-0.11.0-py3-none-any.whl size=599743 sha256=5c3423be4db64dd9395e03ce636c312024541cf97b4e736635d7d2754d6a7a8f\n",
      "  Stored in directory: c:\\users\\juangabriel\\appdata\\local\\pip\\cache\\wheels\\f1\\41\\d0\\1f1acd2606744b6eea651fc3cfcaf3447b2961814eaefb15e9\n",
      "  Building wheel for htmlmin (setup.py): started\n",
      "  Building wheel for htmlmin (setup.py): finished with status 'done'\n",
      "  Created wheel for htmlmin: filename=htmlmin-0.1.12-py3-none-any.whl size=27091 sha256=2bf6fe1c19e7fe30e8b25abeb46328f2dd5fa10c90ff8a4d16a0c39a17906dd7\n",
      "  Stored in directory: c:\\users\\juangabriel\\appdata\\local\\pip\\cache\\wheels\\70\\e1\\52\\5b14d250ba868768823940c3229e9950d201a26d0bd3ee8655\n",
      "Successfully built phik htmlmin\n",
      "Installing collected packages: confuse, scipy, pandas, llvmlite, numba, phik, tangled-up-in-unicode, imagehash, visions, htmlmin, missingno, pandas-profiling\n",
      "  Attempting uninstall: scipy\n",
      "    Found existing installation: scipy 1.2.2\n",
      "    Uninstalling scipy-1.2.2:\n",
      "      Successfully uninstalled scipy-1.2.2\n",
      "  Attempting uninstall: pandas\n",
      "    Found existing installation: pandas 0.24.2\n",
      "    Uninstalling pandas-0.24.2:\n",
      "      Successfully uninstalled pandas-0.24.2\n"
     ]
    },
    {
     "name": "stderr",
     "output_type": "stream",
     "text": [
      "ERROR: Could not install packages due to an EnvironmentError: [WinError 5] Access is denied: 'c:\\\\users\\\\juangabriel\\\\.venvs\\\\lewagon\\\\lib\\\\site-packages\\\\~andas\\\\io\\\\msgpack\\\\_packer.cp37-win_amd64.pyd'\n",
      "Consider using the `--user` option or check the permissions.\n",
      "\n",
      "WARNING: You are using pip version 20.2.4; however, version 20.3.3 is available.\n",
      "You should consider upgrading via the 'c:\\users\\juangabriel\\.venvs\\lewagon\\scripts\\python.exe -m pip install --upgrade pip' command.\n"
     ]
    }
   ],
   "source": [
    "# First, let's install the pandas-profiling package\n",
    "! pip install pandas-profiling"
   ]
  },
  {
   "cell_type": "code",
   "execution_count": 4,
   "metadata": {},
   "outputs": [
    {
     "name": "stderr",
     "output_type": "stream",
     "text": [
      "[autoreload of pandas failed: Traceback (most recent call last):\n",
      "  File \"c:\\users\\juangabriel\\.venvs\\lewagon\\lib\\site-packages\\IPython\\extensions\\autoreload.py\", line 245, in check\n",
      "    superreload(m, reload, self.old_objects)\n",
      "  File \"c:\\users\\juangabriel\\.venvs\\lewagon\\lib\\site-packages\\IPython\\extensions\\autoreload.py\", line 394, in superreload\n",
      "    module = reload(module)\n",
      "  File \"C:\\Users\\JuanGabriel\\anaconda3\\lib\\imp.py\", line 314, in reload\n",
      "    return importlib.reload(module)\n",
      "  File \"C:\\Users\\JuanGabriel\\anaconda3\\lib\\importlib\\__init__.py\", line 169, in reload\n",
      "    _bootstrap._exec(spec, module)\n",
      "  File \"<frozen importlib._bootstrap>\", line 630, in _exec\n",
      "  File \"<frozen importlib._bootstrap_external>\", line 728, in exec_module\n",
      "  File \"<frozen importlib._bootstrap>\", line 219, in _call_with_frames_removed\n",
      "  File \"c:\\users\\juangabriel\\.venvs\\lewagon\\lib\\site-packages\\pandas\\__init__.py\", line 22, in <module>\n",
      "    from pandas.compat.numpy import (\n",
      "ImportError: cannot import name 'np_version_under1p17' from 'pandas.compat.numpy' (c:\\users\\juangabriel\\.venvs\\lewagon\\lib\\site-packages\\pandas\\compat\\numpy\\__init__.py)\n",
      "]\n",
      "[autoreload of pandas._libs failed: Traceback (most recent call last):\n",
      "  File \"c:\\users\\juangabriel\\.venvs\\lewagon\\lib\\site-packages\\IPython\\extensions\\autoreload.py\", line 245, in check\n",
      "    superreload(m, reload, self.old_objects)\n",
      "  File \"c:\\users\\juangabriel\\.venvs\\lewagon\\lib\\site-packages\\IPython\\extensions\\autoreload.py\", line 394, in superreload\n",
      "    module = reload(module)\n",
      "  File \"C:\\Users\\JuanGabriel\\anaconda3\\lib\\imp.py\", line 314, in reload\n",
      "    return importlib.reload(module)\n",
      "  File \"C:\\Users\\JuanGabriel\\anaconda3\\lib\\importlib\\__init__.py\", line 169, in reload\n",
      "    _bootstrap._exec(spec, module)\n",
      "  File \"<frozen importlib._bootstrap>\", line 630, in _exec\n",
      "  File \"<frozen importlib._bootstrap_external>\", line 728, in exec_module\n",
      "  File \"<frozen importlib._bootstrap>\", line 219, in _call_with_frames_removed\n",
      "  File \"c:\\users\\juangabriel\\.venvs\\lewagon\\lib\\site-packages\\pandas\\_libs\\__init__.py\", line 14, in <module>\n",
      "    from pandas._libs.tslibs import (\n",
      "ImportError: cannot import name 'NaTType' from 'pandas._libs.tslibs' (c:\\users\\juangabriel\\.venvs\\lewagon\\lib\\site-packages\\pandas\\_libs\\tslibs\\__init__.py)\n",
      "]\n",
      "[autoreload of pandas._libs.tslibs failed: Traceback (most recent call last):\n",
      "  File \"c:\\users\\juangabriel\\.venvs\\lewagon\\lib\\site-packages\\IPython\\extensions\\autoreload.py\", line 245, in check\n",
      "    superreload(m, reload, self.old_objects)\n",
      "  File \"c:\\users\\juangabriel\\.venvs\\lewagon\\lib\\site-packages\\IPython\\extensions\\autoreload.py\", line 394, in superreload\n",
      "    module = reload(module)\n",
      "  File \"C:\\Users\\JuanGabriel\\anaconda3\\lib\\imp.py\", line 314, in reload\n",
      "    return importlib.reload(module)\n",
      "  File \"C:\\Users\\JuanGabriel\\anaconda3\\lib\\importlib\\__init__.py\", line 169, in reload\n",
      "    _bootstrap._exec(spec, module)\n",
      "  File \"<frozen importlib._bootstrap>\", line 630, in _exec\n",
      "  File \"<frozen importlib._bootstrap_external>\", line 728, in exec_module\n",
      "  File \"<frozen importlib._bootstrap>\", line 219, in _call_with_frames_removed\n",
      "  File \"c:\\users\\juangabriel\\.venvs\\lewagon\\lib\\site-packages\\pandas\\_libs\\tslibs\\__init__.py\", line 30, in <module>\n",
      "    from .conversion import OutOfBoundsTimedelta, localize_pydatetime\n",
      "ImportError: cannot import name 'OutOfBoundsTimedelta' from 'pandas._libs.tslibs.conversion' (c:\\users\\juangabriel\\.venvs\\lewagon\\lib\\site-packages\\pandas\\_libs\\tslibs\\conversion.cp37-win_amd64.pyd)\n",
      "]\n",
      "[autoreload of pandas.core.dtypes.inference failed: Traceback (most recent call last):\n",
      "  File \"c:\\users\\juangabriel\\.venvs\\lewagon\\lib\\site-packages\\IPython\\extensions\\autoreload.py\", line 245, in check\n",
      "    superreload(m, reload, self.old_objects)\n",
      "  File \"c:\\users\\juangabriel\\.venvs\\lewagon\\lib\\site-packages\\IPython\\extensions\\autoreload.py\", line 394, in superreload\n",
      "    module = reload(module)\n",
      "  File \"C:\\Users\\JuanGabriel\\anaconda3\\lib\\imp.py\", line 314, in reload\n",
      "    return importlib.reload(module)\n",
      "  File \"C:\\Users\\JuanGabriel\\anaconda3\\lib\\importlib\\__init__.py\", line 169, in reload\n",
      "    _bootstrap._exec(spec, module)\n",
      "  File \"<frozen importlib._bootstrap>\", line 630, in _exec\n",
      "  File \"<frozen importlib._bootstrap_external>\", line 728, in exec_module\n",
      "  File \"<frozen importlib._bootstrap>\", line 219, in _call_with_frames_removed\n",
      "  File \"c:\\users\\juangabriel\\.venvs\\lewagon\\lib\\site-packages\\pandas\\core\\dtypes\\inference.py\", line 26, in <module>\n",
      "    is_list_like = lib.is_list_like\n",
      "AttributeError: module 'pandas._libs.lib' has no attribute 'is_list_like'\n",
      "]\n",
      "[autoreload of pandas.core.api failed: Traceback (most recent call last):\n",
      "  File \"c:\\users\\juangabriel\\.venvs\\lewagon\\lib\\site-packages\\IPython\\extensions\\autoreload.py\", line 245, in check\n",
      "    superreload(m, reload, self.old_objects)\n",
      "  File \"c:\\users\\juangabriel\\.venvs\\lewagon\\lib\\site-packages\\IPython\\extensions\\autoreload.py\", line 394, in superreload\n",
      "    module = reload(module)\n",
      "  File \"C:\\Users\\JuanGabriel\\anaconda3\\lib\\imp.py\", line 314, in reload\n",
      "    return importlib.reload(module)\n",
      "  File \"C:\\Users\\JuanGabriel\\anaconda3\\lib\\importlib\\__init__.py\", line 169, in reload\n",
      "    _bootstrap._exec(spec, module)\n",
      "  File \"<frozen importlib._bootstrap>\", line 630, in _exec\n",
      "  File \"<frozen importlib._bootstrap_external>\", line 728, in exec_module\n",
      "  File \"<frozen importlib._bootstrap>\", line 219, in _call_with_frames_removed\n",
      "  File \"c:\\users\\juangabriel\\.venvs\\lewagon\\lib\\site-packages\\pandas\\core\\api.py\", line 4, in <module>\n",
      "    from pandas._libs.missing import NA\n",
      "ImportError: cannot import name 'NA' from 'pandas._libs.missing' (c:\\users\\juangabriel\\.venvs\\lewagon\\lib\\site-packages\\pandas\\_libs\\missing.cp37-win_amd64.pyd)\n",
      "]\n",
      "[autoreload of pandas.core.arrays failed: Traceback (most recent call last):\n",
      "  File \"c:\\users\\juangabriel\\.venvs\\lewagon\\lib\\site-packages\\IPython\\extensions\\autoreload.py\", line 245, in check\n",
      "    superreload(m, reload, self.old_objects)\n",
      "  File \"c:\\users\\juangabriel\\.venvs\\lewagon\\lib\\site-packages\\IPython\\extensions\\autoreload.py\", line 394, in superreload\n",
      "    module = reload(module)\n",
      "  File \"C:\\Users\\JuanGabriel\\anaconda3\\lib\\imp.py\", line 314, in reload\n",
      "    return importlib.reload(module)\n",
      "  File \"C:\\Users\\JuanGabriel\\anaconda3\\lib\\importlib\\__init__.py\", line 169, in reload\n",
      "    _bootstrap._exec(spec, module)\n",
      "  File \"<frozen importlib._bootstrap>\", line 630, in _exec\n",
      "  File \"<frozen importlib._bootstrap_external>\", line 728, in exec_module\n",
      "  File \"<frozen importlib._bootstrap>\", line 219, in _call_with_frames_removed\n",
      "  File \"c:\\users\\juangabriel\\.venvs\\lewagon\\lib\\site-packages\\pandas\\core\\arrays\\__init__.py\", line 6, in <module>\n",
      "    from pandas.core.arrays.boolean import BooleanArray\n",
      "  File \"c:\\users\\juangabriel\\.venvs\\lewagon\\lib\\site-packages\\pandas\\core\\arrays\\boolean.py\", line 26, in <module>\n",
      "    from .masked import BaseMaskedArray, BaseMaskedDtype\n",
      "  File \"c:\\users\\juangabriel\\.venvs\\lewagon\\lib\\site-packages\\pandas\\core\\arrays\\masked.py\", line 10, in <module>\n",
      "    from pandas.util._decorators import cache_readonly, doc\n",
      "ImportError: cannot import name 'doc' from 'pandas.util._decorators' (c:\\users\\juangabriel\\.venvs\\lewagon\\lib\\site-packages\\pandas\\util\\_decorators.py)\n",
      "]\n",
      "[autoreload of pandas.core.dtypes.common failed: Traceback (most recent call last):\n",
      "  File \"c:\\users\\juangabriel\\.venvs\\lewagon\\lib\\site-packages\\IPython\\extensions\\autoreload.py\", line 245, in check\n",
      "    superreload(m, reload, self.old_objects)\n",
      "  File \"c:\\users\\juangabriel\\.venvs\\lewagon\\lib\\site-packages\\IPython\\extensions\\autoreload.py\", line 394, in superreload\n",
      "    module = reload(module)\n",
      "  File \"C:\\Users\\JuanGabriel\\anaconda3\\lib\\imp.py\", line 314, in reload\n",
      "    return importlib.reload(module)\n",
      "  File \"C:\\Users\\JuanGabriel\\anaconda3\\lib\\importlib\\__init__.py\", line 169, in reload\n",
      "    _bootstrap._exec(spec, module)\n",
      "  File \"<frozen importlib._bootstrap>\", line 630, in _exec\n",
      "  File \"<frozen importlib._bootstrap_external>\", line 728, in exec_module\n",
      "  File \"<frozen importlib._bootstrap>\", line 219, in _call_with_frames_removed\n",
      "  File \"c:\\users\\juangabriel\\.venvs\\lewagon\\lib\\site-packages\\pandas\\core\\dtypes\\common.py\", line 14, in <module>\n",
      "    from pandas.core.dtypes.base import registry\n",
      "ImportError: cannot import name 'registry' from 'pandas.core.dtypes.base' (c:\\users\\juangabriel\\.venvs\\lewagon\\lib\\site-packages\\pandas\\core\\dtypes\\base.py)\n",
      "]\n",
      "[autoreload of pandas.core.dtypes.dtypes failed: Traceback (most recent call last):\n",
      "  File \"c:\\users\\juangabriel\\.venvs\\lewagon\\lib\\site-packages\\IPython\\extensions\\autoreload.py\", line 245, in check\n",
      "    superreload(m, reload, self.old_objects)\n",
      "  File \"c:\\users\\juangabriel\\.venvs\\lewagon\\lib\\site-packages\\IPython\\extensions\\autoreload.py\", line 394, in superreload\n",
      "    module = reload(module)\n",
      "  File \"C:\\Users\\JuanGabriel\\anaconda3\\lib\\imp.py\", line 314, in reload\n",
      "    return importlib.reload(module)\n",
      "  File \"C:\\Users\\JuanGabriel\\anaconda3\\lib\\importlib\\__init__.py\", line 169, in reload\n",
      "    _bootstrap._exec(spec, module)\n",
      "  File \"<frozen importlib._bootstrap>\", line 630, in _exec\n",
      "  File \"<frozen importlib._bootstrap_external>\", line 728, in exec_module\n",
      "  File \"<frozen importlib._bootstrap>\", line 219, in _call_with_frames_removed\n",
      "  File \"c:\\users\\juangabriel\\.venvs\\lewagon\\lib\\site-packages\\pandas\\core\\dtypes\\dtypes.py\", line 23, in <module>\n",
      "    from pandas._libs.tslibs import NaT, Period, Timestamp, dtypes, timezones, to_offset\n",
      "ImportError: cannot import name 'to_offset' from 'pandas._libs.tslibs' (c:\\users\\juangabriel\\.venvs\\lewagon\\lib\\site-packages\\pandas\\_libs\\tslibs\\__init__.py)\n",
      "]\n",
      "[autoreload of pandas.errors failed: Traceback (most recent call last):\n",
      "  File \"c:\\users\\juangabriel\\.venvs\\lewagon\\lib\\site-packages\\IPython\\extensions\\autoreload.py\", line 245, in check\n",
      "    superreload(m, reload, self.old_objects)\n",
      "  File \"c:\\users\\juangabriel\\.venvs\\lewagon\\lib\\site-packages\\IPython\\extensions\\autoreload.py\", line 394, in superreload\n",
      "    module = reload(module)\n",
      "  File \"C:\\Users\\JuanGabriel\\anaconda3\\lib\\imp.py\", line 314, in reload\n",
      "    return importlib.reload(module)\n",
      "  File \"C:\\Users\\JuanGabriel\\anaconda3\\lib\\importlib\\__init__.py\", line 169, in reload\n",
      "    _bootstrap._exec(spec, module)\n",
      "  File \"<frozen importlib._bootstrap>\", line 630, in _exec\n",
      "  File \"<frozen importlib._bootstrap_external>\", line 728, in exec_module\n",
      "  File \"<frozen importlib._bootstrap>\", line 219, in _call_with_frames_removed\n",
      "  File \"c:\\users\\juangabriel\\.venvs\\lewagon\\lib\\site-packages\\pandas\\errors\\__init__.py\", line 9, in <module>\n",
      "    from pandas._libs.tslibs import OutOfBoundsDatetime, OutOfBoundsTimedelta\n",
      "ImportError: cannot import name 'OutOfBoundsTimedelta' from 'pandas._libs.tslibs' (c:\\users\\juangabriel\\.venvs\\lewagon\\lib\\site-packages\\pandas\\_libs\\tslibs\\__init__.py)\n",
      "]\n",
      "[autoreload of pandas.core.arrays.base failed: Traceback (most recent call last):\n",
      "  File \"c:\\users\\juangabriel\\.venvs\\lewagon\\lib\\site-packages\\IPython\\extensions\\autoreload.py\", line 245, in check\n",
      "    superreload(m, reload, self.old_objects)\n",
      "  File \"c:\\users\\juangabriel\\.venvs\\lewagon\\lib\\site-packages\\IPython\\extensions\\autoreload.py\", line 394, in superreload\n",
      "    module = reload(module)\n",
      "  File \"C:\\Users\\JuanGabriel\\anaconda3\\lib\\imp.py\", line 314, in reload\n",
      "    return importlib.reload(module)\n",
      "  File \"C:\\Users\\JuanGabriel\\anaconda3\\lib\\importlib\\__init__.py\", line 169, in reload\n",
      "    _bootstrap._exec(spec, module)\n",
      "  File \"<frozen importlib._bootstrap>\", line 630, in _exec\n",
      "  File \"<frozen importlib._bootstrap_external>\", line 728, in exec_module\n",
      "  File \"<frozen importlib._bootstrap>\", line 219, in _call_with_frames_removed\n",
      "  File \"c:\\users\\juangabriel\\.venvs\\lewagon\\lib\\site-packages\\pandas\\core\\arrays\\base.py\", line 35, in <module>\n",
      "    from pandas.core.dtypes.cast import maybe_cast_to_extension_array\n",
      "ImportError: cannot import name 'maybe_cast_to_extension_array' from 'pandas.core.dtypes.cast' (c:\\users\\juangabriel\\.venvs\\lewagon\\lib\\site-packages\\pandas\\core\\dtypes\\cast.py)\n",
      "]\n",
      "[autoreload of pandas.core.dtypes.cast failed: Traceback (most recent call last):\n",
      "  File \"c:\\users\\juangabriel\\.venvs\\lewagon\\lib\\site-packages\\IPython\\extensions\\autoreload.py\", line 245, in check\n",
      "    superreload(m, reload, self.old_objects)\n",
      "  File \"c:\\users\\juangabriel\\.venvs\\lewagon\\lib\\site-packages\\IPython\\extensions\\autoreload.py\", line 394, in superreload\n",
      "    module = reload(module)\n",
      "  File \"C:\\Users\\JuanGabriel\\anaconda3\\lib\\imp.py\", line 314, in reload\n",
      "    return importlib.reload(module)\n",
      "  File \"C:\\Users\\JuanGabriel\\anaconda3\\lib\\importlib\\__init__.py\", line 169, in reload\n",
      "    _bootstrap._exec(spec, module)\n",
      "  File \"<frozen importlib._bootstrap>\", line 630, in _exec\n",
      "  File \"<frozen importlib._bootstrap_external>\", line 728, in exec_module\n",
      "  File \"<frozen importlib._bootstrap>\", line 219, in _call_with_frames_removed\n",
      "  File \"c:\\users\\juangabriel\\.venvs\\lewagon\\lib\\site-packages\\pandas\\core\\dtypes\\cast.py\", line 24, in <module>\n",
      "    from pandas._libs.tslibs import (\n",
      "ImportError: cannot import name 'ints_to_pydatetime' from 'pandas._libs.tslibs' (c:\\users\\juangabriel\\.venvs\\lewagon\\lib\\site-packages\\pandas\\_libs\\tslibs\\__init__.py)\n",
      "]\n",
      "[autoreload of pandas.core.dtypes.missing failed: Traceback (most recent call last):\n",
      "  File \"c:\\users\\juangabriel\\.venvs\\lewagon\\lib\\site-packages\\IPython\\extensions\\autoreload.py\", line 245, in check\n",
      "    superreload(m, reload, self.old_objects)\n",
      "  File \"c:\\users\\juangabriel\\.venvs\\lewagon\\lib\\site-packages\\IPython\\extensions\\autoreload.py\", line 394, in superreload\n",
      "    module = reload(module)\n",
      "  File \"C:\\Users\\JuanGabriel\\anaconda3\\lib\\imp.py\", line 314, in reload\n",
      "    return importlib.reload(module)\n",
      "  File \"C:\\Users\\JuanGabriel\\anaconda3\\lib\\importlib\\__init__.py\", line 169, in reload\n",
      "    _bootstrap._exec(spec, module)\n",
      "  File \"<frozen importlib._bootstrap>\", line 630, in _exec\n",
      "  File \"<frozen importlib._bootstrap_external>\", line 728, in exec_module\n",
      "  File \"<frozen importlib._bootstrap>\", line 219, in _call_with_frames_removed\n",
      "  File \"c:\\users\\juangabriel\\.venvs\\lewagon\\lib\\site-packages\\pandas\\core\\dtypes\\missing.py\", line 15, in <module>\n",
      "    from pandas.core.dtypes.common import (\n",
      "ImportError: cannot import name 'DT64NS_DTYPE' from 'pandas.core.dtypes.common' (c:\\users\\juangabriel\\.venvs\\lewagon\\lib\\site-packages\\pandas\\core\\dtypes\\common.py)\n",
      "]\n",
      "[autoreload of pandas.core.common failed: Traceback (most recent call last):\n",
      "  File \"c:\\users\\juangabriel\\.venvs\\lewagon\\lib\\site-packages\\IPython\\extensions\\autoreload.py\", line 245, in check\n",
      "    superreload(m, reload, self.old_objects)\n",
      "  File \"c:\\users\\juangabriel\\.venvs\\lewagon\\lib\\site-packages\\IPython\\extensions\\autoreload.py\", line 394, in superreload\n",
      "    module = reload(module)\n",
      "  File \"C:\\Users\\JuanGabriel\\anaconda3\\lib\\imp.py\", line 314, in reload\n",
      "    return importlib.reload(module)\n",
      "  File \"C:\\Users\\JuanGabriel\\anaconda3\\lib\\importlib\\__init__.py\", line 169, in reload\n",
      "    _bootstrap._exec(spec, module)\n",
      "  File \"<frozen importlib._bootstrap>\", line 630, in _exec\n",
      "  File \"<frozen importlib._bootstrap_external>\", line 728, in exec_module\n",
      "  File \"<frozen importlib._bootstrap>\", line 219, in _call_with_frames_removed\n",
      "  File \"c:\\users\\juangabriel\\.venvs\\lewagon\\lib\\site-packages\\pandas\\core\\common.py\", line 28, in <module>\n",
      "    from pandas.core.dtypes.inference import iterable_not_string\n",
      "ImportError: cannot import name 'iterable_not_string' from 'pandas.core.dtypes.inference' (c:\\users\\juangabriel\\.venvs\\lewagon\\lib\\site-packages\\pandas\\core\\dtypes\\inference.py)\n",
      "]\n",
      "[autoreload of pandas.core.arrays.categorical failed: Traceback (most recent call last):\n",
      "  File \"c:\\users\\juangabriel\\.venvs\\lewagon\\lib\\site-packages\\IPython\\extensions\\autoreload.py\", line 245, in check\n",
      "    superreload(m, reload, self.old_objects)\n",
      "  File \"c:\\users\\juangabriel\\.venvs\\lewagon\\lib\\site-packages\\IPython\\extensions\\autoreload.py\", line 394, in superreload\n",
      "    module = reload(module)\n",
      "  File \"C:\\Users\\JuanGabriel\\anaconda3\\lib\\imp.py\", line 314, in reload\n",
      "    return importlib.reload(module)\n",
      "  File \"C:\\Users\\JuanGabriel\\anaconda3\\lib\\importlib\\__init__.py\", line 169, in reload\n",
      "    _bootstrap._exec(spec, module)\n",
      "  File \"<frozen importlib._bootstrap>\", line 630, in _exec\n",
      "  File \"<frozen importlib._bootstrap_external>\", line 728, in exec_module\n",
      "  File \"<frozen importlib._bootstrap>\", line 219, in _call_with_frames_removed\n",
      "  File \"c:\\users\\juangabriel\\.venvs\\lewagon\\lib\\site-packages\\pandas\\core\\arrays\\categorical.py\", line 13, in <module>\n",
      "    from pandas._libs.lib import no_default\n",
      "ImportError: cannot import name 'no_default' from 'pandas._libs.lib' (c:\\users\\juangabriel\\.venvs\\lewagon\\lib\\site-packages\\pandas\\_libs\\lib.cp37-win_amd64.pyd)\n",
      "]\n",
      "[autoreload of pandas.core.accessor failed: Traceback (most recent call last):\n",
      "  File \"c:\\users\\juangabriel\\.venvs\\lewagon\\lib\\site-packages\\IPython\\extensions\\autoreload.py\", line 245, in check\n",
      "    superreload(m, reload, self.old_objects)\n",
      "  File \"c:\\users\\juangabriel\\.venvs\\lewagon\\lib\\site-packages\\IPython\\extensions\\autoreload.py\", line 410, in superreload\n",
      "    update_generic(old_obj, new_obj)\n",
      "  File \"c:\\users\\juangabriel\\.venvs\\lewagon\\lib\\site-packages\\IPython\\extensions\\autoreload.py\", line 347, in update_generic\n",
      "    update(a, b)\n",
      "  File \"c:\\users\\juangabriel\\.venvs\\lewagon\\lib\\site-packages\\IPython\\extensions\\autoreload.py\", line 302, in update_class\n",
      "    if update_generic(old_obj, new_obj): continue\n",
      "  File \"c:\\users\\juangabriel\\.venvs\\lewagon\\lib\\site-packages\\IPython\\extensions\\autoreload.py\", line 347, in update_generic\n",
      "    update(a, b)\n",
      "  File \"c:\\users\\juangabriel\\.venvs\\lewagon\\lib\\site-packages\\IPython\\extensions\\autoreload.py\", line 266, in update_function\n",
      "    setattr(old, name, getattr(new, name))\n",
      "ValueError: __dir__() requires a code object with 0 free vars, not 1\n",
      "]\n",
      "[autoreload of pandas.core.algorithms failed: Traceback (most recent call last):\n",
      "  File \"c:\\users\\juangabriel\\.venvs\\lewagon\\lib\\site-packages\\IPython\\extensions\\autoreload.py\", line 245, in check\n",
      "    superreload(m, reload, self.old_objects)\n",
      "  File \"c:\\users\\juangabriel\\.venvs\\lewagon\\lib\\site-packages\\IPython\\extensions\\autoreload.py\", line 410, in superreload\n",
      "    update_generic(old_obj, new_obj)\n",
      "  File \"c:\\users\\juangabriel\\.venvs\\lewagon\\lib\\site-packages\\IPython\\extensions\\autoreload.py\", line 347, in update_generic\n",
      "    update(a, b)\n",
      "  File \"c:\\users\\juangabriel\\.venvs\\lewagon\\lib\\site-packages\\IPython\\extensions\\autoreload.py\", line 266, in update_function\n",
      "    setattr(old, name, getattr(new, name))\n",
      "ValueError: factorize() requires a code object with 5 free vars, not 0\n",
      "]\n",
      "[autoreload of pandas.core.base failed: Traceback (most recent call last):\n",
      "  File \"c:\\users\\juangabriel\\.venvs\\lewagon\\lib\\site-packages\\IPython\\extensions\\autoreload.py\", line 245, in check\n",
      "    superreload(m, reload, self.old_objects)\n",
      "  File \"c:\\users\\juangabriel\\.venvs\\lewagon\\lib\\site-packages\\IPython\\extensions\\autoreload.py\", line 394, in superreload\n",
      "    module = reload(module)\n",
      "  File \"C:\\Users\\JuanGabriel\\anaconda3\\lib\\imp.py\", line 314, in reload\n",
      "    return importlib.reload(module)\n",
      "  File \"C:\\Users\\JuanGabriel\\anaconda3\\lib\\importlib\\__init__.py\", line 169, in reload\n",
      "    _bootstrap._exec(spec, module)\n",
      "  File \"<frozen importlib._bootstrap>\", line 630, in _exec\n",
      "  File \"<frozen importlib._bootstrap_external>\", line 728, in exec_module\n",
      "  File \"<frozen importlib._bootstrap>\", line 219, in _call_with_frames_removed\n",
      "  File \"c:\\users\\juangabriel\\.venvs\\lewagon\\lib\\site-packages\\pandas\\core\\base.py\", line 41, in <module>\n",
      "    from pandas.core.arraylike import OpsMixin\n",
      "  File \"c:\\users\\juangabriel\\.venvs\\lewagon\\lib\\site-packages\\pandas\\core\\arraylike.py\", line 16, in <module>\n",
      "    from pandas.core.ops import maybe_dispatch_ufunc_to_dunder_op, roperator\n",
      "ImportError: cannot import name 'maybe_dispatch_ufunc_to_dunder_op' from 'pandas.core.ops' (c:\\users\\juangabriel\\.venvs\\lewagon\\lib\\site-packages\\pandas\\core\\ops.py)\n",
      "]\n",
      "[autoreload of pandas.core.nanops failed: Traceback (most recent call last):\n",
      "  File \"c:\\users\\juangabriel\\.venvs\\lewagon\\lib\\site-packages\\IPython\\extensions\\autoreload.py\", line 245, in check\n",
      "    superreload(m, reload, self.old_objects)\n",
      "  File \"c:\\users\\juangabriel\\.venvs\\lewagon\\lib\\site-packages\\IPython\\extensions\\autoreload.py\", line 394, in superreload\n",
      "    module = reload(module)\n",
      "  File \"C:\\Users\\JuanGabriel\\anaconda3\\lib\\imp.py\", line 314, in reload\n",
      "    return importlib.reload(module)\n",
      "  File \"C:\\Users\\JuanGabriel\\anaconda3\\lib\\importlib\\__init__.py\", line 169, in reload\n",
      "    _bootstrap._exec(spec, module)\n",
      "  File \"<frozen importlib._bootstrap>\", line 630, in _exec\n",
      "  File \"<frozen importlib._bootstrap_external>\", line 728, in exec_module\n",
      "  File \"<frozen importlib._bootstrap>\", line 219, in _call_with_frames_removed\n",
      "  File \"c:\\users\\juangabriel\\.venvs\\lewagon\\lib\\site-packages\\pandas\\core\\nanops.py\", line 15, in <module>\n",
      "    from pandas.core.dtypes.common import (\n",
      "ImportError: cannot import name 'get_dtype' from 'pandas.core.dtypes.common' (c:\\users\\juangabriel\\.venvs\\lewagon\\lib\\site-packages\\pandas\\core\\dtypes\\common.py)\n",
      "]\n",
      "[autoreload of pandas.tseries.offsets failed: Traceback (most recent call last):\n",
      "  File \"c:\\users\\juangabriel\\.venvs\\lewagon\\lib\\site-packages\\IPython\\extensions\\autoreload.py\", line 245, in check\n",
      "    superreload(m, reload, self.old_objects)\n",
      "  File \"c:\\users\\juangabriel\\.venvs\\lewagon\\lib\\site-packages\\IPython\\extensions\\autoreload.py\", line 394, in superreload\n",
      "    module = reload(module)\n",
      "  File \"C:\\Users\\JuanGabriel\\anaconda3\\lib\\imp.py\", line 314, in reload\n",
      "    return importlib.reload(module)\n",
      "  File \"C:\\Users\\JuanGabriel\\anaconda3\\lib\\importlib\\__init__.py\", line 169, in reload\n",
      "    _bootstrap._exec(spec, module)\n",
      "  File \"<frozen importlib._bootstrap>\", line 630, in _exec\n",
      "  File \"<frozen importlib._bootstrap_external>\", line 728, in exec_module\n",
      "  File \"<frozen importlib._bootstrap>\", line 219, in _call_with_frames_removed\n",
      "  File \"c:\\users\\juangabriel\\.venvs\\lewagon\\lib\\site-packages\\pandas\\tseries\\offsets.py\", line 1, in <module>\n",
      "    from pandas._libs.tslibs.offsets import (  # noqa:F401\n",
      "ImportError: cannot import name 'FY5253' from 'pandas._libs.tslibs.offsets' (c:\\users\\juangabriel\\.venvs\\lewagon\\lib\\site-packages\\pandas\\_libs\\tslibs\\offsets.cp37-win_amd64.pyd)\n",
      "]\n",
      "[autoreload of pandas.core.tools.datetimes failed: Traceback (most recent call last):\n",
      "  File \"c:\\users\\juangabriel\\.venvs\\lewagon\\lib\\site-packages\\IPython\\extensions\\autoreload.py\", line 245, in check\n",
      "    superreload(m, reload, self.old_objects)\n",
      "  File \"c:\\users\\juangabriel\\.venvs\\lewagon\\lib\\site-packages\\IPython\\extensions\\autoreload.py\", line 394, in superreload\n",
      "    module = reload(module)\n",
      "  File \"C:\\Users\\JuanGabriel\\anaconda3\\lib\\imp.py\", line 314, in reload\n",
      "    return importlib.reload(module)\n",
      "  File \"C:\\Users\\JuanGabriel\\anaconda3\\lib\\importlib\\__init__.py\", line 169, in reload\n",
      "    _bootstrap._exec(spec, module)\n",
      "  File \"<frozen importlib._bootstrap>\", line 630, in _exec\n",
      "  File \"<frozen importlib._bootstrap_external>\", line 728, in exec_module\n",
      "  File \"<frozen importlib._bootstrap>\", line 219, in _call_with_frames_removed\n",
      "  File \"c:\\users\\juangabriel\\.venvs\\lewagon\\lib\\site-packages\\pandas\\core\\tools\\datetimes.py\", line 20, in <module>\n",
      "    from pandas._libs.tslibs import (\n",
      "ImportError: cannot import name 'nat_strings' from 'pandas._libs.tslibs' (c:\\users\\juangabriel\\.venvs\\lewagon\\lib\\site-packages\\pandas\\_libs\\tslibs\\__init__.py)\n",
      "]\n",
      "[autoreload of pandas.core.arrays.datetimes failed: Traceback (most recent call last):\n",
      "  File \"c:\\users\\juangabriel\\.venvs\\lewagon\\lib\\site-packages\\IPython\\extensions\\autoreload.py\", line 245, in check\n",
      "    superreload(m, reload, self.old_objects)\n",
      "  File \"c:\\users\\juangabriel\\.venvs\\lewagon\\lib\\site-packages\\IPython\\extensions\\autoreload.py\", line 394, in superreload\n",
      "    module = reload(module)\n",
      "  File \"C:\\Users\\JuanGabriel\\anaconda3\\lib\\imp.py\", line 314, in reload\n",
      "    return importlib.reload(module)\n",
      "  File \"C:\\Users\\JuanGabriel\\anaconda3\\lib\\importlib\\__init__.py\", line 169, in reload\n",
      "    _bootstrap._exec(spec, module)\n",
      "  File \"<frozen importlib._bootstrap>\", line 630, in _exec\n",
      "  File \"<frozen importlib._bootstrap_external>\", line 728, in exec_module\n",
      "  File \"<frozen importlib._bootstrap>\", line 219, in _call_with_frames_removed\n",
      "  File \"c:\\users\\juangabriel\\.venvs\\lewagon\\lib\\site-packages\\pandas\\core\\arrays\\datetimes.py\", line 8, in <module>\n",
      "    from pandas._libs.tslibs import (\n",
      "  File \"pandas\\_libs\\tslibs\\tzconversion.pyx\", line 1, in init pandas._libs.tslibs.tzconversion\n",
      "ImportError: pandas._libs.tslibs.ccalendar does not export expected C variable DAY_NANOS\n",
      "]\n",
      "[autoreload of pandas.core.arrays.datetimelike failed: Traceback (most recent call last):\n",
      "  File \"c:\\users\\juangabriel\\.venvs\\lewagon\\lib\\site-packages\\IPython\\extensions\\autoreload.py\", line 245, in check\n",
      "    superreload(m, reload, self.old_objects)\n",
      "  File \"c:\\users\\juangabriel\\.venvs\\lewagon\\lib\\site-packages\\IPython\\extensions\\autoreload.py\", line 394, in superreload\n",
      "    module = reload(module)\n",
      "  File \"C:\\Users\\JuanGabriel\\anaconda3\\lib\\imp.py\", line 314, in reload\n",
      "    return importlib.reload(module)\n",
      "  File \"C:\\Users\\JuanGabriel\\anaconda3\\lib\\importlib\\__init__.py\", line 169, in reload\n",
      "    _bootstrap._exec(spec, module)\n",
      "  File \"<frozen importlib._bootstrap>\", line 630, in _exec\n",
      "  File \"<frozen importlib._bootstrap_external>\", line 728, in exec_module\n",
      "  File \"<frozen importlib._bootstrap>\", line 219, in _call_with_frames_removed\n",
      "  File \"c:\\users\\juangabriel\\.venvs\\lewagon\\lib\\site-packages\\pandas\\core\\arrays\\datetimelike.py\", line 22, in <module>\n",
      "    from pandas._libs.tslibs import (\n",
      "ImportError: cannot import name 'BaseOffset' from 'pandas._libs.tslibs' (c:\\users\\juangabriel\\.venvs\\lewagon\\lib\\site-packages\\pandas\\_libs\\tslibs\\__init__.py)\n",
      "]\n",
      "[autoreload of pandas.tseries.frequencies failed: Traceback (most recent call last):\n",
      "  File \"c:\\users\\juangabriel\\.venvs\\lewagon\\lib\\site-packages\\IPython\\extensions\\autoreload.py\", line 245, in check\n",
      "    superreload(m, reload, self.old_objects)\n",
      "  File \"c:\\users\\juangabriel\\.venvs\\lewagon\\lib\\site-packages\\IPython\\extensions\\autoreload.py\", line 394, in superreload\n",
      "    module = reload(module)\n",
      "  File \"C:\\Users\\JuanGabriel\\anaconda3\\lib\\imp.py\", line 314, in reload\n",
      "    return importlib.reload(module)\n",
      "  File \"C:\\Users\\JuanGabriel\\anaconda3\\lib\\importlib\\__init__.py\", line 169, in reload\n",
      "    _bootstrap._exec(spec, module)\n",
      "  File \"<frozen importlib._bootstrap>\", line 630, in _exec\n",
      "  File \"<frozen importlib._bootstrap_external>\", line 728, in exec_module\n",
      "  File \"<frozen importlib._bootstrap>\", line 219, in _call_with_frames_removed\n",
      "  File \"c:\\users\\juangabriel\\.venvs\\lewagon\\lib\\site-packages\\pandas\\tseries\\frequencies.py\", line 7, in <module>\n",
      "    from pandas._libs.tslibs import Timestamp, tzconversion\n",
      "  File \"pandas\\_libs\\tslibs\\tzconversion.pyx\", line 1, in init pandas._libs.tslibs.tzconversion\n",
      "ImportError: pandas._libs.tslibs.ccalendar does not export expected C variable DAY_NANOS\n",
      "]\n",
      "[autoreload of pandas.core.arrays._ranges failed: Traceback (most recent call last):\n",
      "  File \"c:\\users\\juangabriel\\.venvs\\lewagon\\lib\\site-packages\\IPython\\extensions\\autoreload.py\", line 245, in check\n",
      "    superreload(m, reload, self.old_objects)\n",
      "  File \"c:\\users\\juangabriel\\.venvs\\lewagon\\lib\\site-packages\\IPython\\extensions\\autoreload.py\", line 394, in superreload\n",
      "    module = reload(module)\n",
      "  File \"C:\\Users\\JuanGabriel\\anaconda3\\lib\\imp.py\", line 314, in reload\n",
      "    return importlib.reload(module)\n",
      "  File \"C:\\Users\\JuanGabriel\\anaconda3\\lib\\importlib\\__init__.py\", line 169, in reload\n",
      "    _bootstrap._exec(spec, module)\n",
      "  File \"<frozen importlib._bootstrap>\", line 630, in _exec\n",
      "  File \"<frozen importlib._bootstrap_external>\", line 728, in exec_module\n",
      "  File \"<frozen importlib._bootstrap>\", line 219, in _call_with_frames_removed\n",
      "  File \"c:\\users\\juangabriel\\.venvs\\lewagon\\lib\\site-packages\\pandas\\core\\arrays\\_ranges.py\", line 10, in <module>\n",
      "    from pandas._libs.tslibs import BaseOffset, OutOfBoundsDatetime, Timedelta, Timestamp\n",
      "ImportError: cannot import name 'BaseOffset' from 'pandas._libs.tslibs' (c:\\users\\juangabriel\\.venvs\\lewagon\\lib\\site-packages\\pandas\\_libs\\tslibs\\__init__.py)\n",
      "]\n",
      "[autoreload of pandas.core.arrays.interval failed: Traceback (most recent call last):\n",
      "  File \"c:\\users\\juangabriel\\.venvs\\lewagon\\lib\\site-packages\\IPython\\extensions\\autoreload.py\", line 245, in check\n",
      "    superreload(m, reload, self.old_objects)\n",
      "  File \"c:\\users\\juangabriel\\.venvs\\lewagon\\lib\\site-packages\\IPython\\extensions\\autoreload.py\", line 394, in superreload\n",
      "    module = reload(module)\n",
      "  File \"C:\\Users\\JuanGabriel\\anaconda3\\lib\\imp.py\", line 314, in reload\n",
      "    return importlib.reload(module)\n",
      "  File \"C:\\Users\\JuanGabriel\\anaconda3\\lib\\importlib\\__init__.py\", line 169, in reload\n",
      "    _bootstrap._exec(spec, module)\n",
      "  File \"<frozen importlib._bootstrap>\", line 630, in _exec\n",
      "  File \"<frozen importlib._bootstrap_external>\", line 728, in exec_module\n",
      "  File \"<frozen importlib._bootstrap>\", line 219, in _call_with_frames_removed\n",
      "  File \"c:\\users\\juangabriel\\.venvs\\lewagon\\lib\\site-packages\\pandas\\core\\arrays\\interval.py\", line 10, in <module>\n",
      "    from pandas._libs.interval import (\n",
      "ImportError: cannot import name 'VALID_CLOSED' from 'pandas._libs.interval' (c:\\users\\juangabriel\\.venvs\\lewagon\\lib\\site-packages\\pandas\\_libs\\interval.cp37-win_amd64.pyd)\n",
      "]\n",
      "[autoreload of pandas.core.indexes.base failed: Traceback (most recent call last):\n",
      "  File \"c:\\users\\juangabriel\\.venvs\\lewagon\\lib\\site-packages\\IPython\\extensions\\autoreload.py\", line 245, in check\n",
      "    superreload(m, reload, self.old_objects)\n",
      "  File \"c:\\users\\juangabriel\\.venvs\\lewagon\\lib\\site-packages\\IPython\\extensions\\autoreload.py\", line 394, in superreload\n",
      "    module = reload(module)\n",
      "  File \"C:\\Users\\JuanGabriel\\anaconda3\\lib\\imp.py\", line 314, in reload\n",
      "    return importlib.reload(module)\n",
      "  File \"C:\\Users\\JuanGabriel\\anaconda3\\lib\\importlib\\__init__.py\", line 169, in reload\n",
      "    _bootstrap._exec(spec, module)\n",
      "  File \"<frozen importlib._bootstrap>\", line 630, in _exec\n",
      "  File \"<frozen importlib._bootstrap_external>\", line 728, in exec_module\n",
      "  File \"<frozen importlib._bootstrap>\", line 219, in _call_with_frames_removed\n",
      "  File \"c:\\users\\juangabriel\\.venvs\\lewagon\\lib\\site-packages\\pandas\\core\\indexes\\base.py\", line 27, in <module>\n",
      "    from pandas._libs.lib import is_datetime_array, no_default\n",
      "ImportError: cannot import name 'no_default' from 'pandas._libs.lib' (c:\\users\\juangabriel\\.venvs\\lewagon\\lib\\site-packages\\pandas\\_libs\\lib.cp37-win_amd64.pyd)\n",
      "]\n",
      "[autoreload of pandas.core.arrays.period failed: Traceback (most recent call last):\n",
      "  File \"c:\\users\\juangabriel\\.venvs\\lewagon\\lib\\site-packages\\IPython\\extensions\\autoreload.py\", line 245, in check\n",
      "    superreload(m, reload, self.old_objects)\n",
      "  File \"c:\\users\\juangabriel\\.venvs\\lewagon\\lib\\site-packages\\IPython\\extensions\\autoreload.py\", line 394, in superreload\n",
      "    module = reload(module)\n",
      "  File \"C:\\Users\\JuanGabriel\\anaconda3\\lib\\imp.py\", line 314, in reload\n",
      "    return importlib.reload(module)\n",
      "  File \"C:\\Users\\JuanGabriel\\anaconda3\\lib\\importlib\\__init__.py\", line 169, in reload\n",
      "    _bootstrap._exec(spec, module)\n",
      "  File \"<frozen importlib._bootstrap>\", line 630, in _exec\n",
      "  File \"<frozen importlib._bootstrap_external>\", line 728, in exec_module\n",
      "  File \"<frozen importlib._bootstrap>\", line 219, in _call_with_frames_removed\n",
      "  File \"c:\\users\\juangabriel\\.venvs\\lewagon\\lib\\site-packages\\pandas\\core\\arrays\\period.py\", line 7, in <module>\n",
      "    from pandas._libs.tslibs import (\n",
      "ImportError: cannot import name 'BaseOffset' from 'pandas._libs.tslibs' (c:\\users\\juangabriel\\.venvs\\lewagon\\lib\\site-packages\\pandas\\_libs\\tslibs\\__init__.py)\n",
      "]\n",
      "[autoreload of pandas.core.arrays.timedeltas failed: Traceback (most recent call last):\n",
      "  File \"c:\\users\\juangabriel\\.venvs\\lewagon\\lib\\site-packages\\IPython\\extensions\\autoreload.py\", line 245, in check\n",
      "    superreload(m, reload, self.old_objects)\n",
      "  File \"c:\\users\\juangabriel\\.venvs\\lewagon\\lib\\site-packages\\IPython\\extensions\\autoreload.py\", line 394, in superreload\n",
      "    module = reload(module)\n",
      "  File \"C:\\Users\\JuanGabriel\\anaconda3\\lib\\imp.py\", line 314, in reload\n",
      "    return importlib.reload(module)\n",
      "  File \"C:\\Users\\JuanGabriel\\anaconda3\\lib\\importlib\\__init__.py\", line 169, in reload\n",
      "    _bootstrap._exec(spec, module)\n",
      "  File \"<frozen importlib._bootstrap>\", line 630, in _exec\n",
      "  File \"<frozen importlib._bootstrap_external>\", line 728, in exec_module\n",
      "  File \"<frozen importlib._bootstrap>\", line 219, in _call_with_frames_removed\n",
      "  File \"c:\\users\\juangabriel\\.venvs\\lewagon\\lib\\site-packages\\pandas\\core\\arrays\\timedeltas.py\", line 7, in <module>\n",
      "    from pandas._libs.tslibs import (\n",
      "ImportError: cannot import name 'BaseOffset' from 'pandas._libs.tslibs' (c:\\users\\juangabriel\\.venvs\\lewagon\\lib\\site-packages\\pandas\\_libs\\tslibs\\__init__.py)\n",
      "]\n",
      "[autoreload of pandas.core.arrays.integer failed: Traceback (most recent call last):\n",
      "  File \"c:\\users\\juangabriel\\.venvs\\lewagon\\lib\\site-packages\\IPython\\extensions\\autoreload.py\", line 245, in check\n",
      "    superreload(m, reload, self.old_objects)\n",
      "  File \"c:\\users\\juangabriel\\.venvs\\lewagon\\lib\\site-packages\\IPython\\extensions\\autoreload.py\", line 394, in superreload\n",
      "    module = reload(module)\n",
      "  File \"C:\\Users\\JuanGabriel\\anaconda3\\lib\\imp.py\", line 314, in reload\n",
      "    return importlib.reload(module)\n",
      "  File \"C:\\Users\\JuanGabriel\\anaconda3\\lib\\importlib\\__init__.py\", line 169, in reload\n",
      "    _bootstrap._exec(spec, module)\n",
      "  File \"<frozen importlib._bootstrap>\", line 630, in _exec\n",
      "  File \"<frozen importlib._bootstrap_external>\", line 728, in exec_module\n",
      "  File \"<frozen importlib._bootstrap>\", line 219, in _call_with_frames_removed\n",
      "  File \"c:\\users\\juangabriel\\.venvs\\lewagon\\lib\\site-packages\\pandas\\core\\arrays\\integer.py\", line 29, in <module>\n",
      "    from .masked import BaseMaskedArray, BaseMaskedDtype\n",
      "  File \"c:\\users\\juangabriel\\.venvs\\lewagon\\lib\\site-packages\\pandas\\core\\arrays\\masked.py\", line 23, in <module>\n",
      "    from pandas.core.array_algos import masked_reductions\n",
      "  File \"c:\\users\\juangabriel\\.venvs\\lewagon\\lib\\site-packages\\pandas\\core\\array_algos\\masked_reductions.py\", line 13, in <module>\n",
      "    from pandas.core.nanops import check_below_min_count\n",
      "ImportError: cannot import name 'check_below_min_count' from 'pandas.core.nanops' (c:\\users\\juangabriel\\.venvs\\lewagon\\lib\\site-packages\\pandas\\core\\nanops.py)\n",
      "]\n",
      "[autoreload of pandas.core.arrays.numpy_ failed: Traceback (most recent call last):\n",
      "  File \"c:\\users\\juangabriel\\.venvs\\lewagon\\lib\\site-packages\\IPython\\extensions\\autoreload.py\", line 245, in check\n",
      "    superreload(m, reload, self.old_objects)\n",
      "  File \"c:\\users\\juangabriel\\.venvs\\lewagon\\lib\\site-packages\\IPython\\extensions\\autoreload.py\", line 394, in superreload\n",
      "    module = reload(module)\n",
      "  File \"C:\\Users\\JuanGabriel\\anaconda3\\lib\\imp.py\", line 314, in reload\n",
      "    return importlib.reload(module)\n",
      "  File \"C:\\Users\\JuanGabriel\\anaconda3\\lib\\importlib\\__init__.py\", line 169, in reload\n",
      "    _bootstrap._exec(spec, module)\n",
      "  File \"<frozen importlib._bootstrap>\", line 630, in _exec\n",
      "  File \"<frozen importlib._bootstrap_external>\", line 728, in exec_module\n",
      "  File \"<frozen importlib._bootstrap>\", line 219, in _call_with_frames_removed\n",
      "  File \"c:\\users\\juangabriel\\.venvs\\lewagon\\lib\\site-packages\\pandas\\core\\arrays\\numpy_.py\", line 15, in <module>\n",
      "    from pandas.core.arraylike import OpsMixin\n",
      "  File \"c:\\users\\juangabriel\\.venvs\\lewagon\\lib\\site-packages\\pandas\\core\\arraylike.py\", line 16, in <module>\n",
      "    from pandas.core.ops import maybe_dispatch_ufunc_to_dunder_op, roperator\n",
      "ImportError: cannot import name 'maybe_dispatch_ufunc_to_dunder_op' from 'pandas.core.ops' (c:\\users\\juangabriel\\.venvs\\lewagon\\lib\\site-packages\\pandas\\core\\ops.py)\n",
      "]\n",
      "[autoreload of pandas.core.groupby failed: Traceback (most recent call last):\n",
      "  File \"c:\\users\\juangabriel\\.venvs\\lewagon\\lib\\site-packages\\IPython\\extensions\\autoreload.py\", line 245, in check\n",
      "    superreload(m, reload, self.old_objects)\n",
      "  File \"c:\\users\\juangabriel\\.venvs\\lewagon\\lib\\site-packages\\IPython\\extensions\\autoreload.py\", line 394, in superreload\n",
      "    module = reload(module)\n",
      "  File \"C:\\Users\\JuanGabriel\\anaconda3\\lib\\imp.py\", line 314, in reload\n",
      "    return importlib.reload(module)\n",
      "  File \"C:\\Users\\JuanGabriel\\anaconda3\\lib\\importlib\\__init__.py\", line 169, in reload\n",
      "    _bootstrap._exec(spec, module)\n",
      "  File \"<frozen importlib._bootstrap>\", line 630, in _exec\n",
      "  File \"<frozen importlib._bootstrap_external>\", line 728, in exec_module\n",
      "  File \"<frozen importlib._bootstrap>\", line 219, in _call_with_frames_removed\n",
      "  File \"c:\\users\\juangabriel\\.venvs\\lewagon\\lib\\site-packages\\pandas\\core\\groupby\\__init__.py\", line 1, in <module>\n",
      "    from pandas.core.groupby.generic import DataFrameGroupBy, NamedAgg, SeriesGroupBy\n",
      "ImportError: cannot import name 'NamedAgg' from 'pandas.core.groupby.generic' (c:\\users\\juangabriel\\.venvs\\lewagon\\lib\\site-packages\\pandas\\core\\groupby\\generic.py)\n",
      "]\n",
      "[autoreload of pandas.core.groupby.groupby failed: Traceback (most recent call last):\n",
      "  File \"c:\\users\\juangabriel\\.venvs\\lewagon\\lib\\site-packages\\IPython\\extensions\\autoreload.py\", line 245, in check\n",
      "    superreload(m, reload, self.old_objects)\n",
      "  File \"c:\\users\\juangabriel\\.venvs\\lewagon\\lib\\site-packages\\IPython\\extensions\\autoreload.py\", line 394, in superreload\n",
      "    module = reload(module)\n",
      "  File \"C:\\Users\\JuanGabriel\\anaconda3\\lib\\imp.py\", line 314, in reload\n",
      "    return importlib.reload(module)\n",
      "  File \"C:\\Users\\JuanGabriel\\anaconda3\\lib\\importlib\\__init__.py\", line 169, in reload\n",
      "    _bootstrap._exec(spec, module)\n",
      "  File \"<frozen importlib._bootstrap>\", line 630, in _exec\n",
      "  File \"<frozen importlib._bootstrap_external>\", line 728, in exec_module\n",
      "  File \"<frozen importlib._bootstrap>\", line 219, in _call_with_frames_removed\n",
      "  File \"c:\\users\\juangabriel\\.venvs\\lewagon\\lib\\site-packages\\pandas\\core\\groupby\\groupby.py\", line 75, in <module>\n",
      "    from pandas.core.groupby import base, numba_, ops\n",
      "  File \"c:\\users\\juangabriel\\.venvs\\lewagon\\lib\\site-packages\\pandas\\core\\groupby\\numba_.py\", line 10, in <module>\n",
      "    from pandas.core.util.numba_ import (\n",
      "  File \"c:\\users\\juangabriel\\.venvs\\lewagon\\lib\\site-packages\\pandas\\core\\util\\numba_.py\", line 9, in <module>\n",
      "    from pandas.errors import NumbaUtilError\n",
      "ImportError: cannot import name 'NumbaUtilError' from 'pandas.errors' (c:\\users\\juangabriel\\.venvs\\lewagon\\lib\\site-packages\\pandas\\errors\\__init__.py)\n",
      "]\n",
      "[autoreload of pandas.core.frame failed: Traceback (most recent call last):\n",
      "  File \"c:\\users\\juangabriel\\.venvs\\lewagon\\lib\\site-packages\\IPython\\extensions\\autoreload.py\", line 245, in check\n",
      "    superreload(m, reload, self.old_objects)\n",
      "  File \"c:\\users\\juangabriel\\.venvs\\lewagon\\lib\\site-packages\\IPython\\extensions\\autoreload.py\", line 394, in superreload\n",
      "    module = reload(module)\n",
      "  File \"C:\\Users\\JuanGabriel\\anaconda3\\lib\\imp.py\", line 314, in reload\n",
      "    return importlib.reload(module)\n",
      "  File \"C:\\Users\\JuanGabriel\\anaconda3\\lib\\importlib\\__init__.py\", line 169, in reload\n",
      "    _bootstrap._exec(spec, module)\n",
      "  File \"<frozen importlib._bootstrap>\", line 630, in _exec\n",
      "  File \"<frozen importlib._bootstrap_external>\", line 728, in exec_module\n",
      "  File \"<frozen importlib._bootstrap>\", line 219, in _call_with_frames_removed\n",
      "  File \"c:\\users\\juangabriel\\.venvs\\lewagon\\lib\\site-packages\\pandas\\core\\frame.py\", line 48, in <module>\n",
      "    from pandas._libs.lib import no_default\n",
      "ImportError: cannot import name 'no_default' from 'pandas._libs.lib' (c:\\users\\juangabriel\\.venvs\\lewagon\\lib\\site-packages\\pandas\\_libs\\lib.cp37-win_amd64.pyd)\n",
      "]\n",
      "[autoreload of pandas.core.generic failed: Traceback (most recent call last):\n",
      "  File \"c:\\users\\juangabriel\\.venvs\\lewagon\\lib\\site-packages\\IPython\\extensions\\autoreload.py\", line 245, in check\n",
      "    superreload(m, reload, self.old_objects)\n",
      "  File \"c:\\users\\juangabriel\\.venvs\\lewagon\\lib\\site-packages\\IPython\\extensions\\autoreload.py\", line 394, in superreload\n",
      "    module = reload(module)\n",
      "  File \"C:\\Users\\JuanGabriel\\anaconda3\\lib\\imp.py\", line 314, in reload\n",
      "    return importlib.reload(module)\n",
      "  File \"C:\\Users\\JuanGabriel\\anaconda3\\lib\\importlib\\__init__.py\", line 169, in reload\n",
      "    _bootstrap._exec(spec, module)\n",
      "  File \"<frozen importlib._bootstrap>\", line 630, in _exec\n",
      "  File \"<frozen importlib._bootstrap_external>\", line 728, in exec_module\n",
      "  File \"<frozen importlib._bootstrap>\", line 219, in _call_with_frames_removed\n",
      "  File \"c:\\users\\juangabriel\\.venvs\\lewagon\\lib\\site-packages\\pandas\\core\\generic.py\", line 36, in <module>\n",
      "    from pandas._libs.tslibs import Period, Tick, Timestamp, to_offset\n",
      "ImportError: cannot import name 'Tick' from 'pandas._libs.tslibs' (c:\\users\\juangabriel\\.venvs\\lewagon\\lib\\site-packages\\pandas\\_libs\\tslibs\\__init__.py)\n",
      "]\n",
      "[autoreload of pandas.core.index failed: Traceback (most recent call last):\n",
      "  File \"c:\\users\\juangabriel\\.venvs\\lewagon\\lib\\site-packages\\IPython\\extensions\\autoreload.py\", line 245, in check\n",
      "    superreload(m, reload, self.old_objects)\n",
      "  File \"c:\\users\\juangabriel\\.venvs\\lewagon\\lib\\site-packages\\IPython\\extensions\\autoreload.py\", line 394, in superreload\n",
      "    module = reload(module)\n",
      "  File \"C:\\Users\\JuanGabriel\\anaconda3\\lib\\imp.py\", line 314, in reload\n",
      "    return importlib.reload(module)\n",
      "  File \"C:\\Users\\JuanGabriel\\anaconda3\\lib\\importlib\\__init__.py\", line 169, in reload\n",
      "    _bootstrap._exec(spec, module)\n",
      "  File \"<frozen importlib._bootstrap>\", line 630, in _exec\n",
      "  File \"<frozen importlib._bootstrap_external>\", line 728, in exec_module\n",
      "  File \"<frozen importlib._bootstrap>\", line 219, in _call_with_frames_removed\n",
      "  File \"c:\\users\\juangabriel\\.venvs\\lewagon\\lib\\site-packages\\pandas\\core\\index.py\", line 3, in <module>\n",
      "    from pandas.core.indexes.api import (  # noqa:F401\n",
      "ImportError: cannot import name 'get_objs_combined_axis' from 'pandas.core.indexes.api' (c:\\users\\juangabriel\\.venvs\\lewagon\\lib\\site-packages\\pandas\\core\\indexes\\api.py)\n",
      "]\n",
      "[autoreload of pandas.core.indexes.api failed: Traceback (most recent call last):\n",
      "  File \"c:\\users\\juangabriel\\.venvs\\lewagon\\lib\\site-packages\\IPython\\extensions\\autoreload.py\", line 245, in check\n",
      "    superreload(m, reload, self.old_objects)\n",
      "  File \"c:\\users\\juangabriel\\.venvs\\lewagon\\lib\\site-packages\\IPython\\extensions\\autoreload.py\", line 394, in superreload\n",
      "    module = reload(module)\n",
      "  File \"C:\\Users\\JuanGabriel\\anaconda3\\lib\\imp.py\", line 314, in reload\n",
      "    return importlib.reload(module)\n",
      "  File \"C:\\Users\\JuanGabriel\\anaconda3\\lib\\importlib\\__init__.py\", line 169, in reload\n",
      "    _bootstrap._exec(spec, module)\n",
      "  File \"<frozen importlib._bootstrap>\", line 630, in _exec\n",
      "  File \"<frozen importlib._bootstrap_external>\", line 728, in exec_module\n",
      "  File \"<frozen importlib._bootstrap>\", line 219, in _call_with_frames_removed\n",
      "  File \"c:\\users\\juangabriel\\.venvs\\lewagon\\lib\\site-packages\\pandas\\core\\indexes\\api.py\", line 5, in <module>\n",
      "    from pandas.errors import InvalidIndexError\n",
      "ImportError: cannot import name 'InvalidIndexError' from 'pandas.errors' (c:\\users\\juangabriel\\.venvs\\lewagon\\lib\\site-packages\\pandas\\errors\\__init__.py)\n",
      "]\n",
      "[autoreload of pandas.core.indexes.category failed: Traceback (most recent call last):\n",
      "  File \"c:\\users\\juangabriel\\.venvs\\lewagon\\lib\\site-packages\\IPython\\extensions\\autoreload.py\", line 245, in check\n",
      "    superreload(m, reload, self.old_objects)\n",
      "  File \"c:\\users\\juangabriel\\.venvs\\lewagon\\lib\\site-packages\\IPython\\extensions\\autoreload.py\", line 394, in superreload\n",
      "    module = reload(module)\n",
      "  File \"C:\\Users\\JuanGabriel\\anaconda3\\lib\\imp.py\", line 314, in reload\n",
      "    return importlib.reload(module)\n",
      "  File \"C:\\Users\\JuanGabriel\\anaconda3\\lib\\importlib\\__init__.py\", line 169, in reload\n",
      "    _bootstrap._exec(spec, module)\n",
      "  File \"<frozen importlib._bootstrap>\", line 630, in _exec\n",
      "  File \"<frozen importlib._bootstrap_external>\", line 728, in exec_module\n",
      "  File \"<frozen importlib._bootstrap>\", line 219, in _call_with_frames_removed\n",
      "  File \"c:\\users\\juangabriel\\.venvs\\lewagon\\lib\\site-packages\\pandas\\core\\indexes\\category.py\", line 9, in <module>\n",
      "    from pandas._libs.lib import no_default\n",
      "ImportError: cannot import name 'no_default' from 'pandas._libs.lib' (c:\\users\\juangabriel\\.venvs\\lewagon\\lib\\site-packages\\pandas\\_libs\\lib.cp37-win_amd64.pyd)\n",
      "]\n",
      "[autoreload of pandas.core.indexes.datetimes failed: Traceback (most recent call last):\n",
      "  File \"c:\\users\\juangabriel\\.venvs\\lewagon\\lib\\site-packages\\IPython\\extensions\\autoreload.py\", line 245, in check\n",
      "    superreload(m, reload, self.old_objects)\n",
      "  File \"c:\\users\\juangabriel\\.venvs\\lewagon\\lib\\site-packages\\IPython\\extensions\\autoreload.py\", line 394, in superreload\n",
      "    module = reload(module)\n",
      "  File \"C:\\Users\\JuanGabriel\\anaconda3\\lib\\imp.py\", line 314, in reload\n",
      "    return importlib.reload(module)\n",
      "  File \"C:\\Users\\JuanGabriel\\anaconda3\\lib\\importlib\\__init__.py\", line 169, in reload\n",
      "    _bootstrap._exec(spec, module)\n",
      "  File \"<frozen importlib._bootstrap>\", line 630, in _exec\n",
      "  File \"<frozen importlib._bootstrap_external>\", line 728, in exec_module\n",
      "  File \"<frozen importlib._bootstrap>\", line 219, in _call_with_frames_removed\n",
      "  File \"c:\\users\\juangabriel\\.venvs\\lewagon\\lib\\site-packages\\pandas\\core\\indexes\\datetimes.py\", line 9, in <module>\n",
      "    from pandas._libs.tslibs import (\n",
      "ImportError: cannot import name 'Resolution' from 'pandas._libs.tslibs' (c:\\users\\juangabriel\\.venvs\\lewagon\\lib\\site-packages\\pandas\\_libs\\tslibs\\__init__.py)\n",
      "]\n",
      "[autoreload of pandas.core.indexes.datetimelike failed: Traceback (most recent call last):\n",
      "  File \"c:\\users\\juangabriel\\.venvs\\lewagon\\lib\\site-packages\\IPython\\extensions\\autoreload.py\", line 245, in check\n",
      "    superreload(m, reload, self.old_objects)\n",
      "  File \"c:\\users\\juangabriel\\.venvs\\lewagon\\lib\\site-packages\\IPython\\extensions\\autoreload.py\", line 394, in superreload\n",
      "    module = reload(module)\n",
      "  File \"C:\\Users\\JuanGabriel\\anaconda3\\lib\\imp.py\", line 314, in reload\n",
      "    return importlib.reload(module)\n",
      "  File \"C:\\Users\\JuanGabriel\\anaconda3\\lib\\importlib\\__init__.py\", line 169, in reload\n",
      "    _bootstrap._exec(spec, module)\n",
      "  File \"<frozen importlib._bootstrap>\", line 630, in _exec\n",
      "  File \"<frozen importlib._bootstrap_external>\", line 728, in exec_module\n",
      "  File \"<frozen importlib._bootstrap>\", line 219, in _call_with_frames_removed\n",
      "  File \"c:\\users\\juangabriel\\.venvs\\lewagon\\lib\\site-packages\\pandas\\core\\indexes\\datetimelike.py\", line 10, in <module>\n",
      "    from pandas._libs.tslibs import BaseOffset, Resolution, Tick\n",
      "ImportError: cannot import name 'BaseOffset' from 'pandas._libs.tslibs' (c:\\users\\juangabriel\\.venvs\\lewagon\\lib\\site-packages\\pandas\\_libs\\tslibs\\__init__.py)\n",
      "]\n",
      "[autoreload of pandas.core.indexes.numeric failed: Traceback (most recent call last):\n",
      "  File \"c:\\users\\juangabriel\\.venvs\\lewagon\\lib\\site-packages\\IPython\\extensions\\autoreload.py\", line 245, in check\n",
      "    superreload(m, reload, self.old_objects)\n",
      "  File \"c:\\users\\juangabriel\\.venvs\\lewagon\\lib\\site-packages\\IPython\\extensions\\autoreload.py\", line 394, in superreload\n",
      "    module = reload(module)\n",
      "  File \"C:\\Users\\JuanGabriel\\anaconda3\\lib\\imp.py\", line 314, in reload\n",
      "    return importlib.reload(module)\n",
      "  File \"C:\\Users\\JuanGabriel\\anaconda3\\lib\\importlib\\__init__.py\", line 169, in reload\n",
      "    _bootstrap._exec(spec, module)\n",
      "  File \"<frozen importlib._bootstrap>\", line 630, in _exec\n",
      "  File \"<frozen importlib._bootstrap_external>\", line 728, in exec_module\n",
      "  File \"<frozen importlib._bootstrap>\", line 219, in _call_with_frames_removed\n",
      "  File \"c:\\users\\juangabriel\\.venvs\\lewagon\\lib\\site-packages\\pandas\\core\\indexes\\numeric.py\", line 27, in <module>\n",
      "    from pandas.core.dtypes.missing import is_valid_nat_for_dtype, isna\n",
      "ImportError: cannot import name 'is_valid_nat_for_dtype' from 'pandas.core.dtypes.missing' (c:\\users\\juangabriel\\.venvs\\lewagon\\lib\\site-packages\\pandas\\core\\dtypes\\missing.py)\n",
      "]\n",
      "[autoreload of pandas.core.indexes.interval failed: Traceback (most recent call last):\n",
      "  File \"c:\\users\\juangabriel\\.venvs\\lewagon\\lib\\site-packages\\IPython\\extensions\\autoreload.py\", line 245, in check\n",
      "    superreload(m, reload, self.old_objects)\n",
      "  File \"c:\\users\\juangabriel\\.venvs\\lewagon\\lib\\site-packages\\IPython\\extensions\\autoreload.py\", line 394, in superreload\n",
      "    module = reload(module)\n",
      "  File \"C:\\Users\\JuanGabriel\\anaconda3\\lib\\imp.py\", line 314, in reload\n",
      "    return importlib.reload(module)\n",
      "  File \"C:\\Users\\JuanGabriel\\anaconda3\\lib\\importlib\\__init__.py\", line 169, in reload\n",
      "    _bootstrap._exec(spec, module)\n",
      "  File \"<frozen importlib._bootstrap>\", line 630, in _exec\n",
      "  File \"<frozen importlib._bootstrap_external>\", line 728, in exec_module\n",
      "  File \"<frozen importlib._bootstrap>\", line 219, in _call_with_frames_removed\n",
      "  File \"c:\\users\\juangabriel\\.venvs\\lewagon\\lib\\site-packages\\pandas\\core\\indexes\\interval.py\", line 13, in <module>\n",
      "    from pandas._libs.tslibs import BaseOffset, Timedelta, Timestamp, to_offset\n",
      "ImportError: cannot import name 'BaseOffset' from 'pandas._libs.tslibs' (c:\\users\\juangabriel\\.venvs\\lewagon\\lib\\site-packages\\pandas\\_libs\\tslibs\\__init__.py)\n",
      "]\n",
      "[autoreload of pandas.core.indexes.multi failed: Traceback (most recent call last):\n",
      "  File \"c:\\users\\juangabriel\\.venvs\\lewagon\\lib\\site-packages\\IPython\\extensions\\autoreload.py\", line 245, in check\n",
      "    superreload(m, reload, self.old_objects)\n",
      "  File \"c:\\users\\juangabriel\\.venvs\\lewagon\\lib\\site-packages\\IPython\\extensions\\autoreload.py\", line 394, in superreload\n",
      "    module = reload(module)\n",
      "  File \"C:\\Users\\JuanGabriel\\anaconda3\\lib\\imp.py\", line 314, in reload\n",
      "    return importlib.reload(module)\n",
      "  File \"C:\\Users\\JuanGabriel\\anaconda3\\lib\\importlib\\__init__.py\", line 169, in reload\n",
      "    _bootstrap._exec(spec, module)\n",
      "  File \"<frozen importlib._bootstrap>\", line 630, in _exec\n",
      "  File \"<frozen importlib._bootstrap_external>\", line 728, in exec_module\n",
      "  File \"<frozen importlib._bootstrap>\", line 219, in _call_with_frames_removed\n",
      "  File \"c:\\users\\juangabriel\\.venvs\\lewagon\\lib\\site-packages\\pandas\\core\\indexes\\multi.py\", line 25, in <module>\n",
      "    from pandas.errors import InvalidIndexError, PerformanceWarning, UnsortedIndexError\n",
      "ImportError: cannot import name 'InvalidIndexError' from 'pandas.errors' (c:\\users\\juangabriel\\.venvs\\lewagon\\lib\\site-packages\\pandas\\errors\\__init__.py)\n",
      "]\n",
      "[autoreload of pandas.core.indexes.timedeltas failed: Traceback (most recent call last):\n",
      "  File \"c:\\users\\juangabriel\\.venvs\\lewagon\\lib\\site-packages\\IPython\\extensions\\autoreload.py\", line 245, in check\n",
      "    superreload(m, reload, self.old_objects)\n",
      "  File \"c:\\users\\juangabriel\\.venvs\\lewagon\\lib\\site-packages\\IPython\\extensions\\autoreload.py\", line 394, in superreload\n",
      "    module = reload(module)\n",
      "  File \"C:\\Users\\JuanGabriel\\anaconda3\\lib\\imp.py\", line 314, in reload\n",
      "    return importlib.reload(module)\n",
      "  File \"C:\\Users\\JuanGabriel\\anaconda3\\lib\\importlib\\__init__.py\", line 169, in reload\n",
      "    _bootstrap._exec(spec, module)\n",
      "  File \"<frozen importlib._bootstrap>\", line 630, in _exec\n",
      "  File \"<frozen importlib._bootstrap_external>\", line 728, in exec_module\n",
      "  File \"<frozen importlib._bootstrap>\", line 219, in _call_with_frames_removed\n",
      "  File \"c:\\users\\juangabriel\\.venvs\\lewagon\\lib\\site-packages\\pandas\\core\\indexes\\timedeltas.py\", line 4, in <module>\n",
      "    from pandas._libs.tslibs import Timedelta, to_offset\n",
      "ImportError: cannot import name 'to_offset' from 'pandas._libs.tslibs' (c:\\users\\juangabriel\\.venvs\\lewagon\\lib\\site-packages\\pandas\\_libs\\tslibs\\__init__.py)\n",
      "]\n",
      "[autoreload of pandas.core.indexes.period failed: Traceback (most recent call last):\n",
      "  File \"c:\\users\\juangabriel\\.venvs\\lewagon\\lib\\site-packages\\IPython\\extensions\\autoreload.py\", line 245, in check\n",
      "    superreload(m, reload, self.old_objects)\n",
      "  File \"c:\\users\\juangabriel\\.venvs\\lewagon\\lib\\site-packages\\IPython\\extensions\\autoreload.py\", line 394, in superreload\n",
      "    module = reload(module)\n",
      "  File \"C:\\Users\\JuanGabriel\\anaconda3\\lib\\imp.py\", line 314, in reload\n",
      "    return importlib.reload(module)\n",
      "  File \"C:\\Users\\JuanGabriel\\anaconda3\\lib\\importlib\\__init__.py\", line 169, in reload\n",
      "    _bootstrap._exec(spec, module)\n",
      "  File \"<frozen importlib._bootstrap>\", line 630, in _exec\n",
      "  File \"<frozen importlib._bootstrap_external>\", line 728, in exec_module\n",
      "  File \"<frozen importlib._bootstrap>\", line 219, in _call_with_frames_removed\n",
      "  File \"c:\\users\\juangabriel\\.venvs\\lewagon\\lib\\site-packages\\pandas\\core\\indexes\\period.py\", line 8, in <module>\n",
      "    from pandas._libs.tslibs import BaseOffset, Period, Resolution, Tick\n",
      "ImportError: cannot import name 'BaseOffset' from 'pandas._libs.tslibs' (c:\\users\\juangabriel\\.venvs\\lewagon\\lib\\site-packages\\pandas\\_libs\\tslibs\\__init__.py)\n",
      "]\n",
      "[autoreload of pandas.core.indexes.range failed: Traceback (most recent call last):\n",
      "  File \"c:\\users\\juangabriel\\.venvs\\lewagon\\lib\\site-packages\\IPython\\extensions\\autoreload.py\", line 245, in check\n",
      "    superreload(m, reload, self.old_objects)\n",
      "  File \"c:\\users\\juangabriel\\.venvs\\lewagon\\lib\\site-packages\\IPython\\extensions\\autoreload.py\", line 394, in superreload\n",
      "    module = reload(module)\n",
      "  File \"C:\\Users\\JuanGabriel\\anaconda3\\lib\\imp.py\", line 314, in reload\n",
      "    return importlib.reload(module)\n",
      "  File \"C:\\Users\\JuanGabriel\\anaconda3\\lib\\importlib\\__init__.py\", line 169, in reload\n",
      "    _bootstrap._exec(spec, module)\n",
      "  File \"<frozen importlib._bootstrap>\", line 630, in _exec\n",
      "  File \"<frozen importlib._bootstrap_external>\", line 728, in exec_module\n",
      "  File \"<frozen importlib._bootstrap>\", line 219, in _call_with_frames_removed\n",
      "  File \"c:\\users\\juangabriel\\.venvs\\lewagon\\lib\\site-packages\\pandas\\core\\indexes\\range.py\", line 10, in <module>\n",
      "    from pandas._libs.lib import no_default\n",
      "ImportError: cannot import name 'no_default' from 'pandas._libs.lib' (c:\\users\\juangabriel\\.venvs\\lewagon\\lib\\site-packages\\pandas\\_libs\\lib.cp37-win_amd64.pyd)\n",
      "]\n",
      "[autoreload of pandas.core.indexing failed: Traceback (most recent call last):\n",
      "  File \"c:\\users\\juangabriel\\.venvs\\lewagon\\lib\\site-packages\\IPython\\extensions\\autoreload.py\", line 245, in check\n",
      "    superreload(m, reload, self.old_objects)\n",
      "  File \"c:\\users\\juangabriel\\.venvs\\lewagon\\lib\\site-packages\\IPython\\extensions\\autoreload.py\", line 394, in superreload\n",
      "    module = reload(module)\n",
      "  File \"C:\\Users\\JuanGabriel\\anaconda3\\lib\\imp.py\", line 314, in reload\n",
      "    return importlib.reload(module)\n",
      "  File \"C:\\Users\\JuanGabriel\\anaconda3\\lib\\importlib\\__init__.py\", line 169, in reload\n",
      "    _bootstrap._exec(spec, module)\n",
      "  File \"<frozen importlib._bootstrap>\", line 630, in _exec\n",
      "  File \"<frozen importlib._bootstrap_external>\", line 728, in exec_module\n",
      "  File \"<frozen importlib._bootstrap>\", line 219, in _call_with_frames_removed\n",
      "  File \"c:\\users\\juangabriel\\.venvs\\lewagon\\lib\\site-packages\\pandas\\core\\indexing.py\", line 9, in <module>\n",
      "    from pandas._libs.indexing import NDFrameIndexerBase\n",
      "ImportError: cannot import name 'NDFrameIndexerBase' from 'pandas._libs.indexing' (c:\\users\\juangabriel\\.venvs\\lewagon\\lib\\site-packages\\pandas\\_libs\\indexing.cp37-win_amd64.pyd)\n",
      "]\n",
      "[autoreload of pandas.core.internals failed: Traceback (most recent call last):\n",
      "  File \"c:\\users\\juangabriel\\.venvs\\lewagon\\lib\\site-packages\\IPython\\extensions\\autoreload.py\", line 245, in check\n",
      "    superreload(m, reload, self.old_objects)\n",
      "  File \"c:\\users\\juangabriel\\.venvs\\lewagon\\lib\\site-packages\\IPython\\extensions\\autoreload.py\", line 394, in superreload\n",
      "    module = reload(module)\n",
      "  File \"C:\\Users\\JuanGabriel\\anaconda3\\lib\\imp.py\", line 314, in reload\n",
      "    return importlib.reload(module)\n",
      "  File \"C:\\Users\\JuanGabriel\\anaconda3\\lib\\importlib\\__init__.py\", line 169, in reload\n",
      "    _bootstrap._exec(spec, module)\n",
      "  File \"<frozen importlib._bootstrap>\", line 630, in _exec\n",
      "  File \"<frozen importlib._bootstrap_external>\", line 728, in exec_module\n",
      "  File \"<frozen importlib._bootstrap>\", line 219, in _call_with_frames_removed\n",
      "  File \"c:\\users\\juangabriel\\.venvs\\lewagon\\lib\\site-packages\\pandas\\core\\internals\\__init__.py\", line 1, in <module>\n",
      "    from pandas.core.internals.blocks import (  # io.pytables, io.packers\n",
      "ImportError: cannot import name 'safe_reshape' from 'pandas.core.internals.blocks' (c:\\users\\juangabriel\\.venvs\\lewagon\\lib\\site-packages\\pandas\\core\\internals\\blocks.py)\n",
      "]\n",
      "[autoreload of pandas.core.internals.blocks failed: Traceback (most recent call last):\n",
      "  File \"c:\\users\\juangabriel\\.venvs\\lewagon\\lib\\site-packages\\IPython\\extensions\\autoreload.py\", line 245, in check\n",
      "    superreload(m, reload, self.old_objects)\n",
      "  File \"c:\\users\\juangabriel\\.venvs\\lewagon\\lib\\site-packages\\IPython\\extensions\\autoreload.py\", line 394, in superreload\n",
      "    module = reload(module)\n",
      "  File \"C:\\Users\\JuanGabriel\\anaconda3\\lib\\imp.py\", line 314, in reload\n",
      "    return importlib.reload(module)\n",
      "  File \"C:\\Users\\JuanGabriel\\anaconda3\\lib\\importlib\\__init__.py\", line 169, in reload\n",
      "    _bootstrap._exec(spec, module)\n",
      "  File \"<frozen importlib._bootstrap>\", line 630, in _exec\n",
      "  File \"<frozen importlib._bootstrap_external>\", line 728, in exec_module\n",
      "  File \"<frozen importlib._bootstrap>\", line 219, in _call_with_frames_removed\n",
      "  File \"c:\\users\\juangabriel\\.venvs\\lewagon\\lib\\site-packages\\pandas\\core\\internals\\blocks.py\", line 16, in <module>\n",
      "    from pandas.core.dtypes.cast import (\n",
      "ImportError: cannot import name 'convert_scalar_for_putitemlike' from 'pandas.core.dtypes.cast' (c:\\users\\juangabriel\\.venvs\\lewagon\\lib\\site-packages\\pandas\\core\\dtypes\\cast.py)\n",
      "]\n",
      "[autoreload of pandas.core.internals.managers failed: Traceback (most recent call last):\n",
      "  File \"c:\\users\\juangabriel\\.venvs\\lewagon\\lib\\site-packages\\IPython\\extensions\\autoreload.py\", line 245, in check\n",
      "    superreload(m, reload, self.old_objects)\n",
      "  File \"c:\\users\\juangabriel\\.venvs\\lewagon\\lib\\site-packages\\IPython\\extensions\\autoreload.py\", line 394, in superreload\n",
      "    module = reload(module)\n",
      "  File \"C:\\Users\\JuanGabriel\\anaconda3\\lib\\imp.py\", line 314, in reload\n",
      "    return importlib.reload(module)\n",
      "  File \"C:\\Users\\JuanGabriel\\anaconda3\\lib\\importlib\\__init__.py\", line 169, in reload\n",
      "    _bootstrap._exec(spec, module)\n",
      "  File \"<frozen importlib._bootstrap>\", line 630, in _exec\n",
      "  File \"<frozen importlib._bootstrap_external>\", line 728, in exec_module\n",
      "  File \"<frozen importlib._bootstrap>\", line 219, in _call_with_frames_removed\n",
      "  File \"c:\\users\\juangabriel\\.venvs\\lewagon\\lib\\site-packages\\pandas\\core\\internals\\managers.py\", line 28, in <module>\n",
      "    from pandas.core.dtypes.common import (\n",
      "ImportError: cannot import name 'DT64NS_DTYPE' from 'pandas.core.dtypes.common' (c:\\users\\juangabriel\\.venvs\\lewagon\\lib\\site-packages\\pandas\\core\\dtypes\\common.py)\n",
      "]\n",
      "[autoreload of pandas.core.internals.concat failed: Traceback (most recent call last):\n",
      "  File \"c:\\users\\juangabriel\\.venvs\\lewagon\\lib\\site-packages\\IPython\\extensions\\autoreload.py\", line 245, in check\n",
      "    superreload(m, reload, self.old_objects)\n",
      "  File \"c:\\users\\juangabriel\\.venvs\\lewagon\\lib\\site-packages\\IPython\\extensions\\autoreload.py\", line 394, in superreload\n",
      "    module = reload(module)\n",
      "  File \"C:\\Users\\JuanGabriel\\anaconda3\\lib\\imp.py\", line 314, in reload\n",
      "    return importlib.reload(module)\n",
      "  File \"C:\\Users\\JuanGabriel\\anaconda3\\lib\\importlib\\__init__.py\", line 169, in reload\n",
      "    _bootstrap._exec(spec, module)\n",
      "  File \"<frozen importlib._bootstrap>\", line 630, in _exec\n",
      "  File \"<frozen importlib._bootstrap_external>\", line 728, in exec_module\n",
      "  File \"<frozen importlib._bootstrap>\", line 219, in _call_with_frames_removed\n",
      "  File \"c:\\users\\juangabriel\\.venvs\\lewagon\\lib\\site-packages\\pandas\\core\\internals\\concat.py\", line 12, in <module>\n",
      "    from pandas.core.dtypes.common import (\n",
      "ImportError: cannot import name 'get_dtype' from 'pandas.core.dtypes.common' (c:\\users\\juangabriel\\.venvs\\lewagon\\lib\\site-packages\\pandas\\core\\dtypes\\common.py)\n",
      "]\n",
      "[autoreload of pandas.io.formats.format failed: Traceback (most recent call last):\n",
      "  File \"c:\\users\\juangabriel\\.venvs\\lewagon\\lib\\site-packages\\IPython\\extensions\\autoreload.py\", line 245, in check\n",
      "    superreload(m, reload, self.old_objects)\n",
      "  File \"c:\\users\\juangabriel\\.venvs\\lewagon\\lib\\site-packages\\IPython\\extensions\\autoreload.py\", line 394, in superreload\n",
      "    module = reload(module)\n",
      "  File \"C:\\Users\\JuanGabriel\\anaconda3\\lib\\imp.py\", line 314, in reload\n",
      "    return importlib.reload(module)\n",
      "  File \"C:\\Users\\JuanGabriel\\anaconda3\\lib\\importlib\\__init__.py\", line 169, in reload\n",
      "    _bootstrap._exec(spec, module)\n",
      "  File \"<frozen importlib._bootstrap>\", line 630, in _exec\n",
      "  File \"<frozen importlib._bootstrap_external>\", line 728, in exec_module\n",
      "  File \"<frozen importlib._bootstrap>\", line 219, in _call_with_frames_removed\n",
      "  File \"c:\\users\\juangabriel\\.venvs\\lewagon\\lib\\site-packages\\pandas\\io\\formats\\format.py\", line 37, in <module>\n",
      "    from pandas._libs.missing import NA\n",
      "ImportError: cannot import name 'NA' from 'pandas._libs.missing' (c:\\users\\juangabriel\\.venvs\\lewagon\\lib\\site-packages\\pandas\\_libs\\missing.cp37-win_amd64.pyd)\n",
      "]\n",
      "[autoreload of pandas.core.internals.construction failed: Traceback (most recent call last):\n",
      "  File \"c:\\users\\juangabriel\\.venvs\\lewagon\\lib\\site-packages\\IPython\\extensions\\autoreload.py\", line 245, in check\n",
      "    superreload(m, reload, self.old_objects)\n",
      "  File \"c:\\users\\juangabriel\\.venvs\\lewagon\\lib\\site-packages\\IPython\\extensions\\autoreload.py\", line 394, in superreload\n",
      "    module = reload(module)\n",
      "  File \"C:\\Users\\JuanGabriel\\anaconda3\\lib\\imp.py\", line 314, in reload\n",
      "    return importlib.reload(module)\n",
      "  File \"C:\\Users\\JuanGabriel\\anaconda3\\lib\\importlib\\__init__.py\", line 169, in reload\n",
      "    _bootstrap._exec(spec, module)\n",
      "  File \"<frozen importlib._bootstrap>\", line 630, in _exec\n",
      "  File \"<frozen importlib._bootstrap_external>\", line 728, in exec_module\n",
      "  File \"<frozen importlib._bootstrap>\", line 219, in _call_with_frames_removed\n",
      "  File \"c:\\users\\juangabriel\\.venvs\\lewagon\\lib\\site-packages\\pandas\\core\\internals\\construction.py\", line 14, in <module>\n",
      "    from pandas.core.dtypes.cast import (\n",
      "ImportError: cannot import name 'dict_compat' from 'pandas.core.dtypes.cast' (c:\\users\\juangabriel\\.venvs\\lewagon\\lib\\site-packages\\pandas\\core\\dtypes\\cast.py)\n",
      "]\n",
      "[autoreload of pandas.core.series failed: Traceback (most recent call last):\n",
      "  File \"c:\\users\\juangabriel\\.venvs\\lewagon\\lib\\site-packages\\IPython\\extensions\\autoreload.py\", line 245, in check\n",
      "    superreload(m, reload, self.old_objects)\n",
      "  File \"c:\\users\\juangabriel\\.venvs\\lewagon\\lib\\site-packages\\IPython\\extensions\\autoreload.py\", line 394, in superreload\n",
      "    module = reload(module)\n",
      "  File \"C:\\Users\\JuanGabriel\\anaconda3\\lib\\imp.py\", line 314, in reload\n",
      "    return importlib.reload(module)\n",
      "  File \"C:\\Users\\JuanGabriel\\anaconda3\\lib\\importlib\\__init__.py\", line 169, in reload\n",
      "    _bootstrap._exec(spec, module)\n",
      "  File \"<frozen importlib._bootstrap>\", line 630, in _exec\n",
      "  File \"<frozen importlib._bootstrap_external>\", line 728, in exec_module\n",
      "  File \"<frozen importlib._bootstrap>\", line 219, in _call_with_frames_removed\n",
      "  File \"c:\\users\\juangabriel\\.venvs\\lewagon\\lib\\site-packages\\pandas\\core\\series.py\", line 26, in <module>\n",
      "    from pandas._libs.lib import no_default\n",
      "ImportError: cannot import name 'no_default' from 'pandas._libs.lib' (c:\\users\\juangabriel\\.venvs\\lewagon\\lib\\site-packages\\pandas\\_libs\\lib.cp37-win_amd64.pyd)\n",
      "]\n",
      "[autoreload of pandas.core.indexes.accessors failed: Traceback (most recent call last):\n",
      "  File \"c:\\users\\juangabriel\\.venvs\\lewagon\\lib\\site-packages\\IPython\\extensions\\autoreload.py\", line 245, in check\n",
      "    superreload(m, reload, self.old_objects)\n",
      "  File \"c:\\users\\juangabriel\\.venvs\\lewagon\\lib\\site-packages\\IPython\\extensions\\autoreload.py\", line 394, in superreload\n",
      "    module = reload(module)\n",
      "  File \"C:\\Users\\JuanGabriel\\anaconda3\\lib\\imp.py\", line 314, in reload\n",
      "    return importlib.reload(module)\n",
      "  File \"C:\\Users\\JuanGabriel\\anaconda3\\lib\\importlib\\__init__.py\", line 169, in reload\n",
      "    _bootstrap._exec(spec, module)\n",
      "  File \"<frozen importlib._bootstrap>\", line 630, in _exec\n",
      "  File \"<frozen importlib._bootstrap_external>\", line 728, in exec_module\n",
      "  File \"<frozen importlib._bootstrap>\", line 219, in _call_with_frames_removed\n",
      "  File \"c:\\users\\juangabriel\\.venvs\\lewagon\\lib\\site-packages\\pandas\\core\\indexes\\accessors.py\", line 30, in <module>\n",
      "    class Properties(PandasDelegate, PandasObject, NoNewAttributesMixin):\n",
      "  File \"c:\\users\\juangabriel\\.venvs\\lewagon\\lib\\site-packages\\pandas\\core\\indexes\\accessors.py\", line 31, in Properties\n",
      "    _hidden_attrs = PandasObject._hidden_attrs | {\n",
      "AttributeError: type object 'PandasObject' has no attribute '_hidden_attrs'\n",
      "]\n",
      "[autoreload of pandas.plotting failed: Traceback (most recent call last):\n",
      "  File \"c:\\users\\juangabriel\\.venvs\\lewagon\\lib\\site-packages\\IPython\\extensions\\autoreload.py\", line 245, in check\n",
      "    superreload(m, reload, self.old_objects)\n",
      "  File \"c:\\users\\juangabriel\\.venvs\\lewagon\\lib\\site-packages\\IPython\\extensions\\autoreload.py\", line 394, in superreload\n",
      "    module = reload(module)\n",
      "  File \"C:\\Users\\JuanGabriel\\anaconda3\\lib\\imp.py\", line 314, in reload\n",
      "    return importlib.reload(module)\n",
      "  File \"C:\\Users\\JuanGabriel\\anaconda3\\lib\\importlib\\__init__.py\", line 169, in reload\n",
      "    _bootstrap._exec(spec, module)\n",
      "  File \"<frozen importlib._bootstrap>\", line 630, in _exec\n",
      "  File \"<frozen importlib._bootstrap_external>\", line 728, in exec_module\n",
      "  File \"<frozen importlib._bootstrap>\", line 219, in _call_with_frames_removed\n",
      "  File \"c:\\users\\juangabriel\\.venvs\\lewagon\\lib\\site-packages\\pandas\\plotting\\__init__.py\", line 58, in <module>\n",
      "    from pandas.plotting._core import (\n",
      "ImportError: cannot import name 'PlotAccessor' from 'pandas.plotting._core' (c:\\users\\juangabriel\\.venvs\\lewagon\\lib\\site-packages\\pandas\\plotting\\_core.py)\n",
      "]\n",
      "[autoreload of pandas.plotting._misc failed: Traceback (most recent call last):\n",
      "  File \"c:\\users\\juangabriel\\.venvs\\lewagon\\lib\\site-packages\\IPython\\extensions\\autoreload.py\", line 245, in check\n",
      "    superreload(m, reload, self.old_objects)\n",
      "  File \"c:\\users\\juangabriel\\.venvs\\lewagon\\lib\\site-packages\\IPython\\extensions\\autoreload.py\", line 394, in superreload\n",
      "    module = reload(module)\n",
      "  File \"C:\\Users\\JuanGabriel\\anaconda3\\lib\\imp.py\", line 314, in reload\n",
      "    return importlib.reload(module)\n",
      "  File \"C:\\Users\\JuanGabriel\\anaconda3\\lib\\importlib\\__init__.py\", line 169, in reload\n",
      "    _bootstrap._exec(spec, module)\n",
      "  File \"<frozen importlib._bootstrap>\", line 630, in _exec\n",
      "  File \"<frozen importlib._bootstrap_external>\", line 728, in exec_module\n",
      "  File \"<frozen importlib._bootstrap>\", line 219, in _call_with_frames_removed\n",
      "  File \"c:\\users\\juangabriel\\.venvs\\lewagon\\lib\\site-packages\\pandas\\plotting\\_misc.py\", line 3, in <module>\n",
      "    from pandas.plotting._core import _get_plot_backend\n",
      "ImportError: cannot import name '_get_plot_backend' from 'pandas.plotting._core' (c:\\users\\juangabriel\\.venvs\\lewagon\\lib\\site-packages\\pandas\\plotting\\_core.py)\n",
      "]\n",
      "[autoreload of pandas.core.groupby.generic failed: Traceback (most recent call last):\n",
      "  File \"c:\\users\\juangabriel\\.venvs\\lewagon\\lib\\site-packages\\IPython\\extensions\\autoreload.py\", line 245, in check\n",
      "    superreload(m, reload, self.old_objects)\n",
      "  File \"c:\\users\\juangabriel\\.venvs\\lewagon\\lib\\site-packages\\IPython\\extensions\\autoreload.py\", line 394, in superreload\n",
      "    module = reload(module)\n",
      "  File \"C:\\Users\\JuanGabriel\\anaconda3\\lib\\imp.py\", line 314, in reload\n",
      "    return importlib.reload(module)\n",
      "  File \"C:\\Users\\JuanGabriel\\anaconda3\\lib\\importlib\\__init__.py\", line 169, in reload\n",
      "    _bootstrap._exec(spec, module)\n",
      "  File \"<frozen importlib._bootstrap>\", line 630, in _exec\n",
      "  File \"<frozen importlib._bootstrap_external>\", line 728, in exec_module\n",
      "  File \"<frozen importlib._bootstrap>\", line 219, in _call_with_frames_removed\n",
      "  File \"c:\\users\\juangabriel\\.venvs\\lewagon\\lib\\site-packages\\pandas\\core\\groupby\\generic.py\", line 36, in <module>\n",
      "    from pandas.core.dtypes.cast import (\n",
      "ImportError: cannot import name 'maybe_cast_result_dtype' from 'pandas.core.dtypes.cast' (c:\\users\\juangabriel\\.venvs\\lewagon\\lib\\site-packages\\pandas\\core\\dtypes\\cast.py)\n",
      "]\n",
      "[autoreload of pandas.core.groupby.grouper failed: Traceback (most recent call last):\n",
      "  File \"c:\\users\\juangabriel\\.venvs\\lewagon\\lib\\site-packages\\IPython\\extensions\\autoreload.py\", line 245, in check\n",
      "    superreload(m, reload, self.old_objects)\n",
      "  File \"c:\\users\\juangabriel\\.venvs\\lewagon\\lib\\site-packages\\IPython\\extensions\\autoreload.py\", line 394, in superreload\n",
      "    module = reload(module)\n",
      "  File \"C:\\Users\\JuanGabriel\\anaconda3\\lib\\imp.py\", line 314, in reload\n",
      "    return importlib.reload(module)\n",
      "  File \"C:\\Users\\JuanGabriel\\anaconda3\\lib\\importlib\\__init__.py\", line 169, in reload\n",
      "    _bootstrap._exec(spec, module)\n",
      "  File \"<frozen importlib._bootstrap>\", line 630, in _exec\n",
      "  File \"<frozen importlib._bootstrap_external>\", line 728, in exec_module\n",
      "  File \"<frozen importlib._bootstrap>\", line 219, in _call_with_frames_removed\n",
      "  File \"c:\\users\\juangabriel\\.venvs\\lewagon\\lib\\site-packages\\pandas\\core\\groupby\\grouper.py\", line 11, in <module>\n",
      "    from pandas.errors import InvalidIndexError\n",
      "ImportError: cannot import name 'InvalidIndexError' from 'pandas.errors' (c:\\users\\juangabriel\\.venvs\\lewagon\\lib\\site-packages\\pandas\\errors\\__init__.py)\n",
      "]\n",
      "[autoreload of pandas.core.groupby.ops failed: Traceback (most recent call last):\n",
      "  File \"c:\\users\\juangabriel\\.venvs\\lewagon\\lib\\site-packages\\IPython\\extensions\\autoreload.py\", line 245, in check\n",
      "    superreload(m, reload, self.old_objects)\n",
      "  File \"c:\\users\\juangabriel\\.venvs\\lewagon\\lib\\site-packages\\IPython\\extensions\\autoreload.py\", line 394, in superreload\n",
      "    module = reload(module)\n",
      "  File \"C:\\Users\\JuanGabriel\\anaconda3\\lib\\imp.py\", line 314, in reload\n",
      "    return importlib.reload(module)\n",
      "  File \"C:\\Users\\JuanGabriel\\anaconda3\\lib\\importlib\\__init__.py\", line 169, in reload\n",
      "    _bootstrap._exec(spec, module)\n",
      "  File \"<frozen importlib._bootstrap>\", line 630, in _exec\n",
      "  File \"<frozen importlib._bootstrap_external>\", line 728, in exec_module\n",
      "  File \"<frozen importlib._bootstrap>\", line 219, in _call_with_frames_removed\n",
      "  File \"c:\\users\\juangabriel\\.venvs\\lewagon\\lib\\site-packages\\pandas\\core\\groupby\\ops.py\", line 31, in <module>\n",
      "    from pandas.core.dtypes.cast import (\n",
      "ImportError: cannot import name 'maybe_cast_result' from 'pandas.core.dtypes.cast' (c:\\users\\juangabriel\\.venvs\\lewagon\\lib\\site-packages\\pandas\\core\\dtypes\\cast.py)\n",
      "]\n",
      "[autoreload of pandas.core.reshape.reshape failed: Traceback (most recent call last):\n",
      "  File \"c:\\users\\juangabriel\\.venvs\\lewagon\\lib\\site-packages\\IPython\\extensions\\autoreload.py\", line 245, in check\n",
      "    superreload(m, reload, self.old_objects)\n",
      "  File \"c:\\users\\juangabriel\\.venvs\\lewagon\\lib\\site-packages\\IPython\\extensions\\autoreload.py\", line 394, in superreload\n",
      "    module = reload(module)\n",
      "  File \"C:\\Users\\JuanGabriel\\anaconda3\\lib\\imp.py\", line 314, in reload\n",
      "    return importlib.reload(module)\n",
      "  File \"C:\\Users\\JuanGabriel\\anaconda3\\lib\\importlib\\__init__.py\", line 169, in reload\n",
      "    _bootstrap._exec(spec, module)\n",
      "  File \"<frozen importlib._bootstrap>\", line 630, in _exec\n",
      "  File \"<frozen importlib._bootstrap_external>\", line 728, in exec_module\n",
      "  File \"<frozen importlib._bootstrap>\", line 219, in _call_with_frames_removed\n",
      "  File \"c:\\users\\juangabriel\\.venvs\\lewagon\\lib\\site-packages\\pandas\\core\\reshape\\reshape.py\", line 26, in <module>\n",
      "    from pandas.core.arrays.categorical import factorize_from_iterable\n",
      "ImportError: cannot import name 'factorize_from_iterable' from 'pandas.core.arrays.categorical' (c:\\users\\juangabriel\\.venvs\\lewagon\\lib\\site-packages\\pandas\\core\\arrays\\categorical.py)\n",
      "]\n",
      "[autoreload of pandas.core.computation.eval failed: Traceback (most recent call last):\n",
      "  File \"c:\\users\\juangabriel\\.venvs\\lewagon\\lib\\site-packages\\IPython\\extensions\\autoreload.py\", line 245, in check\n",
      "    superreload(m, reload, self.old_objects)\n",
      "  File \"c:\\users\\juangabriel\\.venvs\\lewagon\\lib\\site-packages\\IPython\\extensions\\autoreload.py\", line 394, in superreload\n",
      "    module = reload(module)\n",
      "  File \"C:\\Users\\JuanGabriel\\anaconda3\\lib\\imp.py\", line 314, in reload\n",
      "    return importlib.reload(module)\n",
      "  File \"C:\\Users\\JuanGabriel\\anaconda3\\lib\\importlib\\__init__.py\", line 169, in reload\n",
      "    _bootstrap._exec(spec, module)\n",
      "  File \"<frozen importlib._bootstrap>\", line 630, in _exec\n",
      "  File \"<frozen importlib._bootstrap_external>\", line 728, in exec_module\n",
      "  File \"<frozen importlib._bootstrap>\", line 219, in _call_with_frames_removed\n",
      "  File \"c:\\users\\juangabriel\\.venvs\\lewagon\\lib\\site-packages\\pandas\\core\\computation\\eval.py\", line 9, in <module>\n",
      "    from pandas._libs.lib import no_default\n",
      "ImportError: cannot import name 'no_default' from 'pandas._libs.lib' (c:\\users\\juangabriel\\.venvs\\lewagon\\lib\\site-packages\\pandas\\_libs\\lib.cp37-win_amd64.pyd)\n",
      "]\n",
      "[autoreload of pandas.core.computation.engines failed: Traceback (most recent call last):\n",
      "  File \"c:\\users\\juangabriel\\.venvs\\lewagon\\lib\\site-packages\\IPython\\extensions\\autoreload.py\", line 245, in check\n",
      "    superreload(m, reload, self.old_objects)\n",
      "  File \"c:\\users\\juangabriel\\.venvs\\lewagon\\lib\\site-packages\\IPython\\extensions\\autoreload.py\", line 394, in superreload\n",
      "    module = reload(module)\n",
      "  File \"C:\\Users\\JuanGabriel\\anaconda3\\lib\\imp.py\", line 314, in reload\n",
      "    return importlib.reload(module)\n",
      "  File \"C:\\Users\\JuanGabriel\\anaconda3\\lib\\importlib\\__init__.py\", line 169, in reload\n",
      "    _bootstrap._exec(spec, module)\n",
      "  File \"<frozen importlib._bootstrap>\", line 630, in _exec\n",
      "  File \"<frozen importlib._bootstrap_external>\", line 728, in exec_module\n",
      "  File \"<frozen importlib._bootstrap>\", line 219, in _call_with_frames_removed\n",
      "  File \"c:\\users\\juangabriel\\.venvs\\lewagon\\lib\\site-packages\\pandas\\core\\computation\\engines.py\", line 8, in <module>\n",
      "    from pandas.core.computation.align import align_terms, reconstruct_object\n",
      "ImportError: cannot import name 'align_terms' from 'pandas.core.computation.align' (c:\\users\\juangabriel\\.venvs\\lewagon\\lib\\site-packages\\pandas\\core\\computation\\align.py)\n",
      "]\n",
      "[autoreload of pandas.core.computation.align failed: Traceback (most recent call last):\n",
      "  File \"c:\\users\\juangabriel\\.venvs\\lewagon\\lib\\site-packages\\IPython\\extensions\\autoreload.py\", line 245, in check\n",
      "    superreload(m, reload, self.old_objects)\n",
      "  File \"c:\\users\\juangabriel\\.venvs\\lewagon\\lib\\site-packages\\IPython\\extensions\\autoreload.py\", line 394, in superreload\n",
      "    module = reload(module)\n",
      "  File \"C:\\Users\\JuanGabriel\\anaconda3\\lib\\imp.py\", line 314, in reload\n",
      "    return importlib.reload(module)\n",
      "  File \"C:\\Users\\JuanGabriel\\anaconda3\\lib\\importlib\\__init__.py\", line 169, in reload\n",
      "    _bootstrap._exec(spec, module)\n",
      "  File \"<frozen importlib._bootstrap>\", line 630, in _exec\n",
      "  File \"<frozen importlib._bootstrap_external>\", line 728, in exec_module\n",
      "  File \"<frozen importlib._bootstrap>\", line 219, in _call_with_frames_removed\n",
      "  File \"c:\\users\\juangabriel\\.venvs\\lewagon\\lib\\site-packages\\pandas\\core\\computation\\align.py\", line 19, in <module>\n",
      "    from pandas.core.computation.common import result_type_many\n",
      "ImportError: cannot import name 'result_type_many' from 'pandas.core.computation.common' (c:\\users\\juangabriel\\.venvs\\lewagon\\lib\\site-packages\\pandas\\core\\computation\\common.py)\n",
      "]\n",
      "[autoreload of pandas.core.computation.ops failed: Traceback (most recent call last):\n",
      "  File \"c:\\users\\juangabriel\\.venvs\\lewagon\\lib\\site-packages\\IPython\\extensions\\autoreload.py\", line 245, in check\n",
      "    superreload(m, reload, self.old_objects)\n",
      "  File \"c:\\users\\juangabriel\\.venvs\\lewagon\\lib\\site-packages\\IPython\\extensions\\autoreload.py\", line 394, in superreload\n",
      "    module = reload(module)\n",
      "  File \"C:\\Users\\JuanGabriel\\anaconda3\\lib\\imp.py\", line 314, in reload\n",
      "    return importlib.reload(module)\n",
      "  File \"C:\\Users\\JuanGabriel\\anaconda3\\lib\\importlib\\__init__.py\", line 169, in reload\n",
      "    _bootstrap._exec(spec, module)\n",
      "  File \"<frozen importlib._bootstrap>\", line 630, in _exec\n",
      "  File \"<frozen importlib._bootstrap_external>\", line 728, in exec_module\n",
      "  File \"<frozen importlib._bootstrap>\", line 219, in _call_with_frames_removed\n",
      "  File \"c:\\users\\juangabriel\\.venvs\\lewagon\\lib\\site-packages\\pandas\\core\\computation\\ops.py\", line 19, in <module>\n",
      "    from pandas.core.computation.scope import DEFAULT_GLOBALS\n",
      "ImportError: cannot import name 'DEFAULT_GLOBALS' from 'pandas.core.computation.scope' (c:\\users\\juangabriel\\.venvs\\lewagon\\lib\\site-packages\\pandas\\core\\computation\\scope.py)\n",
      "]\n",
      "[autoreload of pandas.core.reshape.concat failed: Traceback (most recent call last):\n",
      "  File \"c:\\users\\juangabriel\\.venvs\\lewagon\\lib\\site-packages\\IPython\\extensions\\autoreload.py\", line 245, in check\n",
      "    superreload(m, reload, self.old_objects)\n",
      "  File \"c:\\users\\juangabriel\\.venvs\\lewagon\\lib\\site-packages\\IPython\\extensions\\autoreload.py\", line 394, in superreload\n",
      "    module = reload(module)\n",
      "  File \"C:\\Users\\JuanGabriel\\anaconda3\\lib\\imp.py\", line 314, in reload\n",
      "    return importlib.reload(module)\n",
      "  File \"C:\\Users\\JuanGabriel\\anaconda3\\lib\\importlib\\__init__.py\", line 169, in reload\n",
      "    _bootstrap._exec(spec, module)\n",
      "  File \"<frozen importlib._bootstrap>\", line 630, in _exec\n",
      "  File \"<frozen importlib._bootstrap_external>\", line 728, in exec_module\n",
      "  File \"<frozen importlib._bootstrap>\", line 219, in _call_with_frames_removed\n",
      "  File \"c:\\users\\juangabriel\\.venvs\\lewagon\\lib\\site-packages\\pandas\\core\\reshape\\concat.py\", line 26, in <module>\n",
      "    from pandas.core.arrays.categorical import (\n",
      "ImportError: cannot import name 'factorize_from_iterable' from 'pandas.core.arrays.categorical' (c:\\users\\juangabriel\\.venvs\\lewagon\\lib\\site-packages\\pandas\\core\\arrays\\categorical.py)\n",
      "]\n",
      "[autoreload of pandas.core.reshape.melt failed: Traceback (most recent call last):\n",
      "  File \"c:\\users\\juangabriel\\.venvs\\lewagon\\lib\\site-packages\\IPython\\extensions\\autoreload.py\", line 245, in check\n",
      "    superreload(m, reload, self.old_objects)\n",
      "  File \"c:\\users\\juangabriel\\.venvs\\lewagon\\lib\\site-packages\\IPython\\extensions\\autoreload.py\", line 410, in superreload\n",
      "    update_generic(old_obj, new_obj)\n",
      "  File \"c:\\users\\juangabriel\\.venvs\\lewagon\\lib\\site-packages\\IPython\\extensions\\autoreload.py\", line 347, in update_generic\n",
      "    update(a, b)\n",
      "  File \"c:\\users\\juangabriel\\.venvs\\lewagon\\lib\\site-packages\\IPython\\extensions\\autoreload.py\", line 266, in update_function\n",
      "    setattr(old, name, getattr(new, name))\n",
      "ValueError: lreshape() requires a code object with 0 free vars, not 5\n",
      "]\n",
      "[autoreload of pandas.core.reshape.pivot failed: Traceback (most recent call last):\n",
      "  File \"c:\\users\\juangabriel\\.venvs\\lewagon\\lib\\site-packages\\IPython\\extensions\\autoreload.py\", line 245, in check\n",
      "    superreload(m, reload, self.old_objects)\n",
      "  File \"c:\\users\\juangabriel\\.venvs\\lewagon\\lib\\site-packages\\IPython\\extensions\\autoreload.py\", line 394, in superreload\n",
      "    module = reload(module)\n",
      "  File \"C:\\Users\\JuanGabriel\\anaconda3\\lib\\imp.py\", line 314, in reload\n",
      "    return importlib.reload(module)\n",
      "  File \"C:\\Users\\JuanGabriel\\anaconda3\\lib\\importlib\\__init__.py\", line 169, in reload\n",
      "    _bootstrap._exec(spec, module)\n",
      "  File \"<frozen importlib._bootstrap>\", line 630, in _exec\n",
      "  File \"<frozen importlib._bootstrap_external>\", line 728, in exec_module\n",
      "  File \"<frozen importlib._bootstrap>\", line 219, in _call_with_frames_removed\n",
      "  File \"c:\\users\\juangabriel\\.venvs\\lewagon\\lib\\site-packages\\pandas\\core\\reshape\\pivot.py\", line 26, in <module>\n",
      "    from pandas.core.indexes.api import Index, MultiIndex, get_objs_combined_axis\n",
      "ImportError: cannot import name 'get_objs_combined_axis' from 'pandas.core.indexes.api' (c:\\users\\juangabriel\\.venvs\\lewagon\\lib\\site-packages\\pandas\\core\\indexes\\api.py)\n",
      "]\n",
      "[autoreload of pandas.core.reshape.tile failed: Traceback (most recent call last):\n",
      "  File \"c:\\users\\juangabriel\\.venvs\\lewagon\\lib\\site-packages\\IPython\\extensions\\autoreload.py\", line 245, in check\n",
      "    superreload(m, reload, self.old_objects)\n",
      "  File \"c:\\users\\juangabriel\\.venvs\\lewagon\\lib\\site-packages\\IPython\\extensions\\autoreload.py\", line 394, in superreload\n",
      "    module = reload(module)\n",
      "  File \"C:\\Users\\JuanGabriel\\anaconda3\\lib\\imp.py\", line 314, in reload\n",
      "    return importlib.reload(module)\n",
      "  File \"C:\\Users\\JuanGabriel\\anaconda3\\lib\\importlib\\__init__.py\", line 169, in reload\n",
      "    _bootstrap._exec(spec, module)\n",
      "  File \"<frozen importlib._bootstrap>\", line 630, in _exec\n",
      "  File \"<frozen importlib._bootstrap_external>\", line 728, in exec_module\n",
      "  File \"<frozen importlib._bootstrap>\", line 219, in _call_with_frames_removed\n",
      "  File \"c:\\users\\juangabriel\\.venvs\\lewagon\\lib\\site-packages\\pandas\\core\\reshape\\tile.py\", line 9, in <module>\n",
      "    from pandas.core.dtypes.common import (\n",
      "ImportError: cannot import name 'DT64NS_DTYPE' from 'pandas.core.dtypes.common' (c:\\users\\juangabriel\\.venvs\\lewagon\\lib\\site-packages\\pandas\\core\\dtypes\\common.py)\n",
      "]\n",
      "[autoreload of pandas.io.parsers failed: Traceback (most recent call last):\n",
      "  File \"c:\\users\\juangabriel\\.venvs\\lewagon\\lib\\site-packages\\IPython\\extensions\\autoreload.py\", line 245, in check\n",
      "    superreload(m, reload, self.old_objects)\n",
      "  File \"c:\\users\\juangabriel\\.venvs\\lewagon\\lib\\site-packages\\IPython\\extensions\\autoreload.py\", line 394, in superreload\n",
      "    module = reload(module)\n",
      "  File \"C:\\Users\\JuanGabriel\\anaconda3\\lib\\imp.py\", line 314, in reload\n",
      "    return importlib.reload(module)\n",
      "  File \"C:\\Users\\JuanGabriel\\anaconda3\\lib\\importlib\\__init__.py\", line 169, in reload\n",
      "    _bootstrap._exec(spec, module)\n",
      "  File \"<frozen importlib._bootstrap>\", line 630, in _exec\n",
      "  File \"<frozen importlib._bootstrap_external>\", line 728, in exec_module\n",
      "  File \"<frozen importlib._bootstrap>\", line 219, in _call_with_frames_removed\n",
      "  File \"c:\\users\\juangabriel\\.venvs\\lewagon\\lib\\site-packages\\pandas\\io\\parsers.py\", line 32, in <module>\n",
      "    from pandas._libs.parsers import STR_NA_VALUES\n",
      "ImportError: cannot import name 'STR_NA_VALUES' from 'pandas._libs.parsers' (c:\\users\\juangabriel\\.venvs\\lewagon\\lib\\site-packages\\pandas\\_libs\\parsers.cp37-win_amd64.pyd)\n",
      "]\n",
      "[autoreload of pandas.io.feather_format failed: Traceback (most recent call last):\n",
      "  File \"c:\\users\\juangabriel\\.venvs\\lewagon\\lib\\site-packages\\IPython\\extensions\\autoreload.py\", line 245, in check\n",
      "    superreload(m, reload, self.old_objects)\n",
      "  File \"c:\\users\\juangabriel\\.venvs\\lewagon\\lib\\site-packages\\IPython\\extensions\\autoreload.py\", line 394, in superreload\n",
      "    module = reload(module)\n",
      "  File \"C:\\Users\\JuanGabriel\\anaconda3\\lib\\imp.py\", line 314, in reload\n",
      "    return importlib.reload(module)\n",
      "  File \"C:\\Users\\JuanGabriel\\anaconda3\\lib\\importlib\\__init__.py\", line 169, in reload\n",
      "    _bootstrap._exec(spec, module)\n",
      "  File \"<frozen importlib._bootstrap>\", line 630, in _exec\n",
      "  File \"<frozen importlib._bootstrap_external>\", line 728, in exec_module\n",
      "  File \"<frozen importlib._bootstrap>\", line 219, in _call_with_frames_removed\n",
      "  File \"c:\\users\\juangabriel\\.venvs\\lewagon\\lib\\site-packages\\pandas\\io\\feather_format.py\", line 15, in <module>\n",
      "    @doc(storage_options=generic._shared_docs[\"storage_options\"])\n",
      "KeyError: 'storage_options'\n",
      "]\n",
      "[autoreload of pandas.io.html failed: Traceback (most recent call last):\n",
      "  File \"c:\\users\\juangabriel\\.venvs\\lewagon\\lib\\site-packages\\IPython\\extensions\\autoreload.py\", line 245, in check\n",
      "    superreload(m, reload, self.old_objects)\n",
      "  File \"c:\\users\\juangabriel\\.venvs\\lewagon\\lib\\site-packages\\IPython\\extensions\\autoreload.py\", line 410, in superreload\n",
      "    update_generic(old_obj, new_obj)\n",
      "  File \"c:\\users\\juangabriel\\.venvs\\lewagon\\lib\\site-packages\\IPython\\extensions\\autoreload.py\", line 347, in update_generic\n",
      "    update(a, b)\n",
      "  File \"c:\\users\\juangabriel\\.venvs\\lewagon\\lib\\site-packages\\IPython\\extensions\\autoreload.py\", line 266, in update_function\n",
      "    setattr(old, name, getattr(new, name))\n",
      "ValueError: read_html() requires a code object with 0 free vars, not 4\n",
      "]\n",
      "[autoreload of pandas.io.json failed: Traceback (most recent call last):\n",
      "  File \"c:\\users\\juangabriel\\.venvs\\lewagon\\lib\\site-packages\\IPython\\extensions\\autoreload.py\", line 245, in check\n",
      "    superreload(m, reload, self.old_objects)\n",
      "  File \"c:\\users\\juangabriel\\.venvs\\lewagon\\lib\\site-packages\\IPython\\extensions\\autoreload.py\", line 394, in superreload\n",
      "    module = reload(module)\n",
      "  File \"C:\\Users\\JuanGabriel\\anaconda3\\lib\\imp.py\", line 314, in reload\n",
      "    return importlib.reload(module)\n",
      "  File \"C:\\Users\\JuanGabriel\\anaconda3\\lib\\importlib\\__init__.py\", line 169, in reload\n",
      "    _bootstrap._exec(spec, module)\n",
      "  File \"<frozen importlib._bootstrap>\", line 630, in _exec\n",
      "  File \"<frozen importlib._bootstrap_external>\", line 728, in exec_module\n",
      "  File \"<frozen importlib._bootstrap>\", line 219, in _call_with_frames_removed\n",
      "  File \"c:\\users\\juangabriel\\.venvs\\lewagon\\lib\\site-packages\\pandas\\io\\json\\__init__.py\", line 1, in <module>\n",
      "    from pandas.io.json._json import dumps, loads, read_json, to_json\n",
      "  File \"c:\\users\\juangabriel\\.venvs\\lewagon\\lib\\site-packages\\pandas\\io\\json\\_json.py\", line 21, in <module>\n",
      "    from pandas.core.dtypes.common import ensure_str, is_period_dtype\n",
      "ImportError: cannot import name 'ensure_str' from 'pandas.core.dtypes.common' (c:\\users\\juangabriel\\.venvs\\lewagon\\lib\\site-packages\\pandas\\core\\dtypes\\common.py)\n",
      "]\n",
      "[autoreload of pandas.api failed: Traceback (most recent call last):\n",
      "  File \"c:\\users\\juangabriel\\.venvs\\lewagon\\lib\\site-packages\\IPython\\extensions\\autoreload.py\", line 245, in check\n",
      "    superreload(m, reload, self.old_objects)\n",
      "  File \"c:\\users\\juangabriel\\.venvs\\lewagon\\lib\\site-packages\\IPython\\extensions\\autoreload.py\", line 394, in superreload\n",
      "    module = reload(module)\n",
      "  File \"C:\\Users\\JuanGabriel\\anaconda3\\lib\\imp.py\", line 314, in reload\n",
      "    return importlib.reload(module)\n",
      "  File \"C:\\Users\\JuanGabriel\\anaconda3\\lib\\importlib\\__init__.py\", line 169, in reload\n",
      "    _bootstrap._exec(spec, module)\n",
      "  File \"<frozen importlib._bootstrap>\", line 630, in _exec\n",
      "  File \"<frozen importlib._bootstrap_external>\", line 728, in exec_module\n",
      "  File \"<frozen importlib._bootstrap>\", line 219, in _call_with_frames_removed\n",
      "  File \"c:\\users\\juangabriel\\.venvs\\lewagon\\lib\\site-packages\\pandas\\api\\__init__.py\", line 2, in <module>\n",
      "    from pandas.api import extensions, indexers, types  # noqa\n",
      "  File \"c:\\users\\juangabriel\\.venvs\\lewagon\\lib\\site-packages\\pandas\\api\\indexers\\__init__.py\", line 6, in <module>\n",
      "    from pandas.core.window.indexers import (\n",
      "ModuleNotFoundError: No module named 'pandas.core.window.indexers'; 'pandas.core.window' is not a package\n",
      "]\n",
      "[autoreload of pandas.api.extensions failed: Traceback (most recent call last):\n",
      "  File \"c:\\users\\juangabriel\\.venvs\\lewagon\\lib\\site-packages\\IPython\\extensions\\autoreload.py\", line 245, in check\n",
      "    superreload(m, reload, self.old_objects)\n",
      "  File \"c:\\users\\juangabriel\\.venvs\\lewagon\\lib\\site-packages\\IPython\\extensions\\autoreload.py\", line 394, in superreload\n",
      "    module = reload(module)\n",
      "  File \"C:\\Users\\JuanGabriel\\anaconda3\\lib\\imp.py\", line 314, in reload\n",
      "    return importlib.reload(module)\n",
      "  File \"C:\\Users\\JuanGabriel\\anaconda3\\lib\\importlib\\__init__.py\", line 169, in reload\n",
      "    _bootstrap._exec(spec, module)\n",
      "  File \"<frozen importlib._bootstrap>\", line 630, in _exec\n",
      "  File \"<frozen importlib._bootstrap_external>\", line 728, in exec_module\n",
      "  File \"<frozen importlib._bootstrap>\", line 219, in _call_with_frames_removed\n",
      "  File \"c:\\users\\juangabriel\\.venvs\\lewagon\\lib\\site-packages\\pandas\\api\\extensions\\__init__.py\", line 5, in <module>\n",
      "    from pandas._libs.lib import no_default\n",
      "ImportError: cannot import name 'no_default' from 'pandas._libs.lib' (c:\\users\\juangabriel\\.venvs\\lewagon\\lib\\site-packages\\pandas\\_libs\\lib.cp37-win_amd64.pyd)\n",
      "]\n",
      "[autoreload of pandas.io.parquet failed: Traceback (most recent call last):\n",
      "  File \"c:\\users\\juangabriel\\.venvs\\lewagon\\lib\\site-packages\\IPython\\extensions\\autoreload.py\", line 245, in check\n",
      "    superreload(m, reload, self.old_objects)\n",
      "  File \"c:\\users\\juangabriel\\.venvs\\lewagon\\lib\\site-packages\\IPython\\extensions\\autoreload.py\", line 394, in superreload\n",
      "    module = reload(module)\n",
      "  File \"C:\\Users\\JuanGabriel\\anaconda3\\lib\\imp.py\", line 314, in reload\n",
      "    return importlib.reload(module)\n",
      "  File \"C:\\Users\\JuanGabriel\\anaconda3\\lib\\importlib\\__init__.py\", line 169, in reload\n",
      "    _bootstrap._exec(spec, module)\n",
      "  File \"<frozen importlib._bootstrap>\", line 630, in _exec\n",
      "  File \"<frozen importlib._bootstrap_external>\", line 728, in exec_module\n",
      "  File \"<frozen importlib._bootstrap>\", line 219, in _call_with_frames_removed\n",
      "  File \"c:\\users\\juangabriel\\.venvs\\lewagon\\lib\\site-packages\\pandas\\io\\parquet.py\", line 321, in <module>\n",
      "    @doc(storage_options=generic._shared_docs[\"storage_options\"])\n",
      "KeyError: 'storage_options'\n",
      "]\n",
      "[autoreload of pandas.io.pickle failed: Traceback (most recent call last):\n",
      "  File \"c:\\users\\juangabriel\\.venvs\\lewagon\\lib\\site-packages\\IPython\\extensions\\autoreload.py\", line 245, in check\n",
      "    superreload(m, reload, self.old_objects)\n",
      "  File \"c:\\users\\juangabriel\\.venvs\\lewagon\\lib\\site-packages\\IPython\\extensions\\autoreload.py\", line 394, in superreload\n",
      "    module = reload(module)\n",
      "  File \"C:\\Users\\JuanGabriel\\anaconda3\\lib\\imp.py\", line 314, in reload\n",
      "    return importlib.reload(module)\n",
      "  File \"C:\\Users\\JuanGabriel\\anaconda3\\lib\\importlib\\__init__.py\", line 169, in reload\n",
      "    _bootstrap._exec(spec, module)\n",
      "  File \"<frozen importlib._bootstrap>\", line 630, in _exec\n",
      "  File \"<frozen importlib._bootstrap_external>\", line 728, in exec_module\n",
      "  File \"<frozen importlib._bootstrap>\", line 219, in _call_with_frames_removed\n",
      "  File \"c:\\users\\juangabriel\\.venvs\\lewagon\\lib\\site-packages\\pandas\\io\\pickle.py\", line 15, in <module>\n",
      "    @doc(storage_options=generic._shared_docs[\"storage_options\"])\n",
      "KeyError: 'storage_options'\n",
      "]\n",
      "[autoreload of pandas.compat.pickle_compat failed: Traceback (most recent call last):\n",
      "  File \"c:\\users\\juangabriel\\.venvs\\lewagon\\lib\\site-packages\\IPython\\extensions\\autoreload.py\", line 245, in check\n",
      "    superreload(m, reload, self.old_objects)\n",
      "  File \"c:\\users\\juangabriel\\.venvs\\lewagon\\lib\\site-packages\\IPython\\extensions\\autoreload.py\", line 394, in superreload\n",
      "    module = reload(module)\n",
      "  File \"C:\\Users\\JuanGabriel\\anaconda3\\lib\\imp.py\", line 314, in reload\n",
      "    return importlib.reload(module)\n",
      "  File \"C:\\Users\\JuanGabriel\\anaconda3\\lib\\importlib\\__init__.py\", line 169, in reload\n",
      "    _bootstrap._exec(spec, module)\n",
      "  File \"<frozen importlib._bootstrap>\", line 630, in _exec\n",
      "  File \"<frozen importlib._bootstrap_external>\", line 728, in exec_module\n",
      "  File \"<frozen importlib._bootstrap>\", line 219, in _call_with_frames_removed\n",
      "  File \"c:\\users\\juangabriel\\.venvs\\lewagon\\lib\\site-packages\\pandas\\compat\\pickle_compat.py\", line 12, in <module>\n",
      "    from pandas._libs.tslibs import BaseOffset\n",
      "ImportError: cannot import name 'BaseOffset' from 'pandas._libs.tslibs' (c:\\users\\juangabriel\\.venvs\\lewagon\\lib\\site-packages\\pandas\\_libs\\tslibs\\__init__.py)\n",
      "]\n",
      "[autoreload of pandas.io.pytables failed: Traceback (most recent call last):\n",
      "  File \"c:\\users\\juangabriel\\.venvs\\lewagon\\lib\\site-packages\\IPython\\extensions\\autoreload.py\", line 245, in check\n",
      "    superreload(m, reload, self.old_objects)\n",
      "  File \"c:\\users\\juangabriel\\.venvs\\lewagon\\lib\\site-packages\\IPython\\extensions\\autoreload.py\", line 394, in superreload\n",
      "    module = reload(module)\n",
      "  File \"C:\\Users\\JuanGabriel\\anaconda3\\lib\\imp.py\", line 314, in reload\n",
      "    return importlib.reload(module)\n",
      "  File \"C:\\Users\\JuanGabriel\\anaconda3\\lib\\importlib\\__init__.py\", line 169, in reload\n",
      "    _bootstrap._exec(spec, module)\n",
      "  File \"<frozen importlib._bootstrap>\", line 630, in _exec\n",
      "  File \"<frozen importlib._bootstrap_external>\", line 728, in exec_module\n",
      "  File \"<frozen importlib._bootstrap>\", line 219, in _call_with_frames_removed\n",
      "  File \"c:\\users\\juangabriel\\.venvs\\lewagon\\lib\\site-packages\\pandas\\io\\pytables.py\", line 33, in <module>\n",
      "    from pandas.compat.pickle_compat import patch_pickle\n",
      "ImportError: cannot import name 'patch_pickle' from 'pandas.compat.pickle_compat' (c:\\users\\juangabriel\\.venvs\\lewagon\\lib\\site-packages\\pandas\\compat\\pickle_compat.py)\n",
      "]\n",
      "[autoreload of pandas.core.computation.expr failed: Traceback (most recent call last):\n",
      "  File \"c:\\users\\juangabriel\\.venvs\\lewagon\\lib\\site-packages\\IPython\\extensions\\autoreload.py\", line 245, in check\n",
      "    superreload(m, reload, self.old_objects)\n",
      "  File \"c:\\users\\juangabriel\\.venvs\\lewagon\\lib\\site-packages\\IPython\\extensions\\autoreload.py\", line 394, in superreload\n",
      "    module = reload(module)\n",
      "  File \"C:\\Users\\JuanGabriel\\anaconda3\\lib\\imp.py\", line 314, in reload\n",
      "    return importlib.reload(module)\n",
      "  File \"C:\\Users\\JuanGabriel\\anaconda3\\lib\\importlib\\__init__.py\", line 169, in reload\n",
      "    _bootstrap._exec(spec, module)\n",
      "  File \"<frozen importlib._bootstrap>\", line 630, in _exec\n",
      "  File \"<frozen importlib._bootstrap_external>\", line 728, in exec_module\n",
      "  File \"<frozen importlib._bootstrap>\", line 219, in _call_with_frames_removed\n",
      "  File \"c:\\users\\juangabriel\\.venvs\\lewagon\\lib\\site-packages\\pandas\\core\\computation\\expr.py\", line 16, in <module>\n",
      "    from pandas.core.computation.ops import (\n",
      "ImportError: cannot import name 'ARITH_OPS_SYMS' from 'pandas.core.computation.ops' (c:\\users\\juangabriel\\.venvs\\lewagon\\lib\\site-packages\\pandas\\core\\computation\\ops.py)\n",
      "]\n",
      "[autoreload of pandas.io.stata failed: Traceback (most recent call last):\n",
      "  File \"c:\\users\\juangabriel\\.venvs\\lewagon\\lib\\site-packages\\IPython\\extensions\\autoreload.py\", line 245, in check\n",
      "    superreload(m, reload, self.old_objects)\n",
      "  File \"c:\\users\\juangabriel\\.venvs\\lewagon\\lib\\site-packages\\IPython\\extensions\\autoreload.py\", line 394, in superreload\n",
      "    module = reload(module)\n",
      "  File \"C:\\Users\\JuanGabriel\\anaconda3\\lib\\imp.py\", line 314, in reload\n",
      "    return importlib.reload(module)\n",
      "  File \"C:\\Users\\JuanGabriel\\anaconda3\\lib\\importlib\\__init__.py\", line 169, in reload\n",
      "    _bootstrap._exec(spec, module)\n",
      "  File \"<frozen importlib._bootstrap>\", line 630, in _exec\n",
      "  File \"<frozen importlib._bootstrap_external>\", line 728, in exec_module\n",
      "  File \"<frozen importlib._bootstrap>\", line 219, in _call_with_frames_removed\n",
      "  File \"c:\\users\\juangabriel\\.venvs\\lewagon\\lib\\site-packages\\pandas\\io\\stata.py\", line 2060, in <module>\n",
      "    @doc(storage_options=generic._shared_docs[\"storage_options\"])\n",
      "KeyError: 'storage_options'\n",
      "]\n",
      "[autoreload of pandas.testing failed: Traceback (most recent call last):\n",
      "  File \"c:\\users\\juangabriel\\.venvs\\lewagon\\lib\\site-packages\\IPython\\extensions\\autoreload.py\", line 245, in check\n",
      "    superreload(m, reload, self.old_objects)\n",
      "  File \"c:\\users\\juangabriel\\.venvs\\lewagon\\lib\\site-packages\\IPython\\extensions\\autoreload.py\", line 394, in superreload\n",
      "    module = reload(module)\n",
      "  File \"C:\\Users\\JuanGabriel\\anaconda3\\lib\\imp.py\", line 314, in reload\n",
      "    return importlib.reload(module)\n",
      "  File \"C:\\Users\\JuanGabriel\\anaconda3\\lib\\importlib\\__init__.py\", line 169, in reload\n",
      "    _bootstrap._exec(spec, module)\n",
      "  File \"<frozen importlib._bootstrap>\", line 630, in _exec\n",
      "  File \"<frozen importlib._bootstrap_external>\", line 728, in exec_module\n",
      "  File \"<frozen importlib._bootstrap>\", line 219, in _call_with_frames_removed\n",
      "  File \"c:\\users\\juangabriel\\.venvs\\lewagon\\lib\\site-packages\\pandas\\testing.py\", line 5, in <module>\n",
      "    from pandas._testing import (\n",
      "  File \"c:\\users\\juangabriel\\.venvs\\lewagon\\lib\\site-packages\\pandas\\_testing.py\", line 26, in <module>\n",
      "    from pandas._libs.lib import no_default\n",
      "ImportError: cannot import name 'no_default' from 'pandas._libs.lib' (c:\\users\\juangabriel\\.venvs\\lewagon\\lib\\site-packages\\pandas\\_libs\\lib.cp37-win_amd64.pyd)\n",
      "]\n",
      "[autoreload of pandas.util.testing failed: Traceback (most recent call last):\n",
      "  File \"c:\\users\\juangabriel\\.venvs\\lewagon\\lib\\site-packages\\IPython\\extensions\\autoreload.py\", line 245, in check\n",
      "    superreload(m, reload, self.old_objects)\n",
      "  File \"c:\\users\\juangabriel\\.venvs\\lewagon\\lib\\site-packages\\IPython\\extensions\\autoreload.py\", line 394, in superreload\n",
      "    module = reload(module)\n",
      "  File \"C:\\Users\\JuanGabriel\\anaconda3\\lib\\imp.py\", line 314, in reload\n",
      "    return importlib.reload(module)\n",
      "  File \"C:\\Users\\JuanGabriel\\anaconda3\\lib\\importlib\\__init__.py\", line 169, in reload\n",
      "    _bootstrap._exec(spec, module)\n",
      "  File \"<frozen importlib._bootstrap>\", line 630, in _exec\n",
      "  File \"<frozen importlib._bootstrap_external>\", line 728, in exec_module\n",
      "  File \"<frozen importlib._bootstrap>\", line 219, in _call_with_frames_removed\n",
      "  File \"c:\\users\\juangabriel\\.venvs\\lewagon\\lib\\site-packages\\pandas\\util\\testing.py\", line 3, in <module>\n",
      "    from pandas._testing import *  # noqa\n",
      "  File \"c:\\users\\juangabriel\\.venvs\\lewagon\\lib\\site-packages\\pandas\\_testing.py\", line 26, in <module>\n",
      "    from pandas._libs.lib import no_default\n",
      "ImportError: cannot import name 'no_default' from 'pandas._libs.lib' (c:\\users\\juangabriel\\.venvs\\lewagon\\lib\\site-packages\\pandas\\_libs\\lib.cp37-win_amd64.pyd)\n",
      "]\n",
      "[autoreload of pandas.arrays failed: Traceback (most recent call last):\n",
      "  File \"c:\\users\\juangabriel\\.venvs\\lewagon\\lib\\site-packages\\IPython\\extensions\\autoreload.py\", line 245, in check\n",
      "    superreload(m, reload, self.old_objects)\n",
      "  File \"c:\\users\\juangabriel\\.venvs\\lewagon\\lib\\site-packages\\IPython\\extensions\\autoreload.py\", line 394, in superreload\n",
      "    module = reload(module)\n",
      "  File \"C:\\Users\\JuanGabriel\\anaconda3\\lib\\imp.py\", line 314, in reload\n",
      "    return importlib.reload(module)\n",
      "  File \"C:\\Users\\JuanGabriel\\anaconda3\\lib\\importlib\\__init__.py\", line 169, in reload\n",
      "    _bootstrap._exec(spec, module)\n",
      "  File \"<frozen importlib._bootstrap>\", line 630, in _exec\n",
      "  File \"<frozen importlib._bootstrap_external>\", line 728, in exec_module\n",
      "  File \"<frozen importlib._bootstrap>\", line 219, in _call_with_frames_removed\n",
      "  File \"c:\\users\\juangabriel\\.venvs\\lewagon\\lib\\site-packages\\pandas\\arrays\\__init__.py\", line 6, in <module>\n",
      "    from pandas.core.arrays import (\n",
      "ImportError: cannot import name 'BooleanArray' from 'pandas.core.arrays' (c:\\users\\juangabriel\\.venvs\\lewagon\\lib\\site-packages\\pandas\\core\\arrays\\__init__.py)\n",
      "]\n",
      "The syntax of the command is incorrect.\n"
     ]
    }
   ],
   "source": [
    "# And create a new \"04-Decision-Science/reports\" folder \n",
    "!mkdir -p ../../data/reports"
   ]
  },
  {
   "cell_type": "code",
   "execution_count": 6,
   "metadata": {},
   "outputs": [
    {
     "ename": "ModuleNotFoundError",
     "evalue": "No module named 'pandas_profiling'",
     "output_type": "error",
     "traceback": [
      "\u001b[1;31m---------------------------------------------------------------------------\u001b[0m",
      "\u001b[1;31mModuleNotFoundError\u001b[0m                       Traceback (most recent call last)",
      "\u001b[1;32m<ipython-input-6-0ef11c7482f4>\u001b[0m in \u001b[0;36m<module>\u001b[1;34m\u001b[0m\n\u001b[1;32m----> 1\u001b[1;33m \u001b[1;32mimport\u001b[0m \u001b[0mpandas_profiling\u001b[0m\u001b[1;33m\u001b[0m\u001b[1;33m\u001b[0m\u001b[0m\n\u001b[0m\u001b[0;32m      2\u001b[0m datasets_to_profile = ['orders', 'products', 'sellers',\n\u001b[0;32m      3\u001b[0m                   \u001b[1;34m'customers'\u001b[0m\u001b[1;33m,\u001b[0m \u001b[1;34m'order_reviews'\u001b[0m\u001b[1;33m,\u001b[0m\u001b[1;33m\u001b[0m\u001b[1;33m\u001b[0m\u001b[0m\n\u001b[0;32m      4\u001b[0m                   'order_items']\n\u001b[0;32m      5\u001b[0m \u001b[1;33m\u001b[0m\u001b[0m\n",
      "\u001b[1;31mModuleNotFoundError\u001b[0m: No module named 'pandas_profiling'"
     ]
    }
   ],
   "source": [
    "import pandas_profiling\n",
    "datasets_to_profile = ['orders', 'products', 'sellers',\n",
    "                  'customers', 'order_reviews',\n",
    "                  'order_items']"
   ]
  },
  {
   "cell_type": "code",
   "execution_count": null,
   "metadata": {},
   "outputs": [],
   "source": [
    "# YOUR CODE: Create and save one html report per dataset to profile (it takes some time to run!)"
   ]
  },
  {
   "cell_type": "markdown",
   "metadata": {},
   "source": [
    "Take 10 min to read the reports, and feel free to add insights of your choice to your db.lewagon.org schema"
   ]
  },
  {
   "cell_type": "markdown",
   "metadata": {},
   "source": [
    "### 2 - Create a matching table"
   ]
  },
  {
   "cell_type": "markdown",
   "metadata": {},
   "source": [
    "Looking at our schema, it would be best to create a central `matching_table` that will join the most important foreign keys together, for later use\n",
    "\n",
    "❓Create the `matching_table`, a DataFrame with the following columns (below).  \n",
    "Use outer joins to make sure you don't lose any information at this stage."
   ]
  },
  {
   "cell_type": "code",
   "execution_count": 93,
   "metadata": {},
   "outputs": [],
   "source": [
    "columns_matching_table = [\n",
    "    \"order_id\",\n",
    "    \"review_id\",\n",
    "    \"customer_id\",\n",
    "    \"product_id\",\n",
    "    \"seller_id\",\n",
    "]"
   ]
  },
  {
   "cell_type": "code",
   "execution_count": 5,
   "metadata": {},
   "outputs": [],
   "source": [
    "# Select only the columns of interest in the various dataframes of interest, before proceeding to any merge"
   ]
  },
  {
   "cell_type": "code",
   "execution_count": 6,
   "metadata": {},
   "outputs": [],
   "source": [
    "# Inspect the cardinality of each DataFrame using pd.DataFrame.shape and pd.Series.nunique()"
   ]
  },
  {
   "cell_type": "code",
   "execution_count": 7,
   "metadata": {},
   "outputs": [],
   "source": [
    "# Carefully merge DataFrames"
   ]
  },
  {
   "cell_type": "code",
   "execution_count": 8,
   "metadata": {},
   "outputs": [],
   "source": [
    "# Inspect the cardinality and `nunique` of the final DataFrame. It should match (114100, 5)"
   ]
  },
  {
   "cell_type": "markdown",
   "metadata": {},
   "source": [
    "### 3 - Save your logic in `data.py` \n",
    "\n",
    "❓Copy your logic into `get_matching_table()` in `data.py` and run the cell below to check your code!"
   ]
  },
  {
   "cell_type": "code",
   "execution_count": null,
   "metadata": {},
   "outputs": [],
   "source": [
    "from nbresult import ChallengeResult\n",
    "from olist.data import Olist\n",
    "\n",
    "data = Olist().get_matching_table()\n",
    "\n",
    "result = ChallengeResult('matching_table',\n",
    "    shape=data.shape,\n",
    "    columns=sorted(list(data.columns)) \n",
    ")\n",
    "result.write()\n",
    "print(result.check())"
   ]
  }
 ],
 "metadata": {
  "kernelspec": {
   "display_name": "Python 3",
   "language": "python",
   "name": "python3"
  },
  "language_info": {
   "codemirror_mode": {
    "name": "ipython",
    "version": 3
   },
   "file_extension": ".py",
   "mimetype": "text/x-python",
   "name": "python",
   "nbconvert_exporter": "python",
   "pygments_lexer": "ipython3",
<<<<<<< HEAD
   "version": "3.7.6"
=======
   "version": "3.8.5"
>>>>>>> ed84f4924f1bf0df867b2d7f11cc743eb8c06727
  },
  "toc": {
   "base_numbering": 1,
   "nav_menu": {},
   "number_sections": false,
   "sideBar": true,
   "skip_h1_title": false,
   "title_cell": "Table of Contents",
   "title_sidebar": "Contents",
   "toc_cell": false,
   "toc_position": {},
   "toc_section_display": true,
   "toc_window_display": false
  },
  "varInspector": {
   "cols": {
    "lenName": 16,
    "lenType": 16,
    "lenVar": 40
   },
   "kernels_config": {
    "python": {
     "delete_cmd_postfix": "",
     "delete_cmd_prefix": "del ",
     "library": "var_list.py",
     "varRefreshCmd": "print(var_dic_list())"
    },
    "r": {
     "delete_cmd_postfix": ") ",
     "delete_cmd_prefix": "rm(",
     "library": "var_list.r",
     "varRefreshCmd": "cat(var_dic_list()) "
    }
   },
   "types_to_exclude": [
    "module",
    "function",
    "builtin_function_or_method",
    "instance",
    "_Feature"
   ],
   "window_display": false
  }
 },
 "nbformat": 4,
 "nbformat_minor": 4
}
